Workbook

Sheet تعريف المواد
B1: اسم القسم / | C1: قسم تقنيات صناعة الأطراف والمساند
B2: المرحلة / | C2: الثانية / الكورس الاول / صباحي
D3: الرجوع الى الصفحة الرئيسية
A4: ت | B4: اسم المادة | C4: اسم مدرس المادة | D4: عدد الوحدات
A5: 1 | B5: تصنيع مقومات | C5: م.د صفا مسير | D5: 17
A6: 2 | B6: امراض وتشوهات الاطراف | C6: د. علي ساجد | D6: 2
A7: 3 | B7: بايو ميكانيك | C7: م.م صالح مطشر | D7: 3
A8: 4 | B8: تشريح الأطراف العليا | C8: م.م براء جليل سعيد | D8: 3
A9: 5 | B9: بدائل الاطرا ف العليا | C9: م.م دعاء يوسف محمد | D9: 5
A10: 6 | B10: خواص مواد | C10: م.م مهند عزيز | D10: 2
A11: 7 | B11: اللغة العربية | C11: م.م. حيدر اعلان | D11: 2
A12: 8 | B12: إجراءات البحث | C12: م.م. حيدر اعلان | D12: 2
A13: 9
A14: 10

Sheet تعريف الاسماء
A2: ت | B2: عمود1 | C2: الشعبة
A3: 1 | B3: احمدعدي هريبد بريو
A4: 2 | B4: احمد نزار عباس غبن
A5: 3 | B5: استبرق مرتضى عبد شهيد | D5: الرجوع الى الصفحة الرئيسية
A6: 4 | B6: اسراء عمارحاكم وحيد
A7: 5 | B7: افراح نصير علي عودة
A8: 6 | B8: امجد نعيم داود سلمان
A9: 7 | B9: امير سرحان كاطع فرهود
A10: 8 | B10: امير عبد الهادي عبد الأمير
A11: 9 | B11: ايات رزاق جبر جاسم
A12: 10 | B12: ايمان فاضل جنابي مزعل
A13: 11 | B13: بتول خضير شلال رميح
A14: 12 | B14: بتول سعود علكو صباح
A15: 13 | B15: بتول عبد المطلب جابر ناصر
A16: 14 | B16: بشائررياض دحام حسين
A17: 15 | B17: بنين باسم عبد الحسين كاظم
... A167: 165 | B167: يوسف علي حمزة شنان
A168: 166
A169: 167
A170: 168
A171: 169
A172: 170
A173: 171
A174: 172
A175: 173
A176: 174
A177: 175
A178: 176
A179: 177
... A402: 400

Sheet الرئيسية
F1: برنامج غيابات الطلبة ( الصفحة الرئيسية )
G3: ادخــــــال أســـــماء الطـــــلبـــــــــة | K3: 1 | L3: =IF('تعريف المواد'!B5<=" ","لا توجد مادة",'تعريف المواد'!B5) -> تصنيع مقومات
G5: ادخـــــــال أســــماء المــــــــــــواد | K5: 2 | L5: =IF('تعريف المواد'!B6<=" ","لا توجد مادة",'تعريف المواد'!B6) -> امراض وتشوهات الاطراف
G7: الامـــــــــــــــــــــــــر الإداري (تنبيه) | K7: 3 | L7: =IF('تعريف المواد'!B7<=" ","لا توجد مادة",'تعريف المواد'!B7) -> بايو ميكانيك
G9: الامر الإداري (انذار اولي) | K9: 4 | L9: =IF('تعريف المواد'!B8<=" ","لا توجد مادة",'تعريف المواد'!B8) -> تشريح الأطراف العليا
G11: الامر الإداري (انذار نهائي) | K11: 5 | L11: =IF('تعريف المواد'!B9<=" ","لا توجد مادة",'تعريف المواد'!B9) -> بدائل الاطرا ف العليا
G13: مجموع غيابات الطالب | K13: 6 | L13: =IF('تعريف المواد'!B10<=" ","لا توجد مادة",'تعريف المواد'!B10) -> خواص مواد
K15: 7 | L15: =IF('تعريف المواد'!B11<=" ","لا توجد مادة",'تعريف المواد'!B11) -> اللغة العربية
K17: 8 | L17: =IF('تعريف المواد'!B12<=" ","لا توجد مادة",'تعريف المواد'!B12) -> إجراءات البحث
K19: 9 | L19: =IF('تعريف المواد'!B13<=" ","لا توجد مادة",'تعريف المواد'!B13) -> لا توجد مادة
K21: 10 | L21: =IF('تعريف المواد'!B14<=" ","لا توجد مادة",'تعريف المواد'!B14) -> لا توجد مادة

Sheet مادة 1
B1: الـقـسـم / | C1: ='تعريف المواد'!C1 -> قسم تقنيات صناعة الأطراف والمساند | U1: المادة | AA1: مدرس المادة | AF1: عدد الساعات
B2: المرحلة / | C2: ='تعريف المواد'!C2 -> الثانية / الكورس الاول / صباحي | U2: ='تعريف المواد'!B5 -> تصنيع مقومات | AA2: ='تعريف المواد'!C5 -> م.د صفا مسير | AG2: ='تعريف المواد'!D5 -> 17
A3: عمود1 | B3: عمود2 | C3: عمود3 | D3: عمود4 | E3: عمود5 | F3: عمود6 | G3: عمود7 | H3: عمود8 | I3: عمود9 | J3: عمود10 | K3: عمود11 | L3: عمود12 | M3: عمود13 | N3: عمود14 | O3: عمود15 | P3: عمود16 | Q3: عمود17 | R3: عمود18 | S3: عمود19 | T3: عمود20 | U3: عمود21 | V3: عمود22 | W3: عمود23 | X3: عمود24 | Y3: عمود25 | Z3: عمود26 | AA3: عمود27 | AB3: عمود28 | AC3: عمود29 | AD3: عمود30 | AE3: عمود31 | AF3: عمود32 | AG3: عمود33 | AH3: عمود34 | AI3: عمود35 | AJ3: عمود36
AI4: =IF(AH4>0,AH4/($AG$2*30),"-") -> - | AJ4: =IF(AH4>=3*$AG$2,"انذار نهائي",IF(AH4>=2*$AG$2,"انذار",IF(AH4>=$AG$2,"تنبيه","")))
A5: ت | B5: الاسم الثلاثي | C5: الشعبة | D5: الاسبوع 1 | E5: الاسبوع 2 | F5: الاسبوع 3 | G5: الاسبوع 4 | H5: الاسبوع 5 | I5: الاسبوع 6 | J5: الاسبوع 7 | K5: الاسبوع 8 | L5: الاسبوع 9 | M5: الاسبوع 10 | N5: الاسبوع 11 | O5: الاسبوع 12 | P5: الاسبوع 13 | Q5: الاسبوع 14 | R5: الاسبوع 15 | S5: الاسبوع 16 | T5: الاسبوع 17 | U5: الاسبوع 18 | V5: الاسبوع 19 | W5: الاسبوع 20 | X5: الاسبوع 21 | Y5: الاسبوع 22 | Z5: الاسبوع 23 | AA5: الاسبوع 24 | AB5: الاسبوع 25 | AC5: الاسبوع 26 | AD5: الاسبوع 27 | AE5: الاسبوع 28 | AF5: الاسبوع 29 | AG5: الاسبوع 30 | AH5: مجموع الغيابات | AI5: نسبة الغيابات | AJ5: نوع العقوبة
A6: 1 | B6: =IF('تعريف الاسماء'!B3<=" "," ",'تعريف الاسماء'!B3) -> احمدعدي هريبد بريو | AH6: =SUM(D6:AG6) -> 0 | AI6: =(IF(AH6>0,(ROUND((AH6/($AG$2*30))*100,0))/100,"-")) -> - | AJ6: =IF(AH6>=3*$AG$2,"انذار نهائي",IF(AH6>=2*$AG$2,"انذار",IF(AH6>=$AG$2,"تنبيه","")))
A7: 2 | B7: =IF('تعريف الاسماء'!B4<=" "," ",'تعريف الاسماء'!B4) -> احمد نزار عباس غبن | AH7: =SUM(D7:AG7) -> 0 | AI7: =(IF(AH7>0,(ROUND((AH7/($AG$2*30))*100,0))/100,"-")) -> - | AJ7: =IF(AH7>=3*$AG$2,"انذار نهائي",IF(AH7>=2*$AG$2,"انذار",IF(AH7>=$AG$2,"تنبيه","")))
A8: 3 | B8: =IF('تعريف الاسماء'!B5<=" "," ",'تعريف الاسماء'!B5) -> استبرق مرتضى عبد شهيد | AH8: =SUM(D8:AG8) -> 0 | AI8: =(IF(AH8>0,(ROUND((AH8/($AG$2*30))*100,0))/100,"-")) -> - | AJ8: =IF(AH8>=3*$AG$2,"انذار نهائي",IF(AH8>=2*$AG$2,"انذار",IF(AH8>=$AG$2,"تنبيه","")))
A9: 4 | B9: =IF('تعريف الاسماء'!B6<=" "," ",'تعريف الاسماء'!B6) -> اسراء عمارحاكم وحيد | AH9: =SUM(D9:AG9) -> 0 | AI9: =(IF(AH9>0,(ROUND((AH9/($AG$2*30))*100,0))/100,"-")) -> - | AJ9: =IF(AH9>=3*$AG$2,"انذار نهائي",IF(AH9>=2*$AG$2,"انذار",IF(AH9>=$AG$2,"تنبيه","")))
A10: 5 | B10: =IF('تعريف الاسماء'!B7<=" "," ",'تعريف الاسماء'!B7) -> افراح نصير علي عودة | AH10: =SUM(D10:AG10) -> 0 | AI10: =(IF(AH10>0,(ROUND((AH10/($AG$2*30))*100,0))/100,"-")) -> - | AJ10: =IF(AH10>=3*$AG$2,"انذار نهائي",IF(AH10>=2*$AG$2,"انذار",IF(AH10>=$AG$2,"تنبيه","")))
A11: 6 | B11: =IF('تعريف الاسماء'!B8<=" "," ",'تعريف الاسماء'!B8) -> امجد نعيم داود سلمان | AH11: =SUM(D11:AG11) -> 0 | AI11: =(IF(AH11>0,(ROUND((AH11/($AG$2*30))*100,0))/100,"-")) -> - | AJ11: =IF(AH11>=3*$AG$2,"انذار نهائي",IF(AH11>=2*$AG$2,"انذار",IF(AH11>=$AG$2,"تنبيه","")))
A12: 7 | B12: =IF('تعريف الاسماء'!B9<=" "," ",'تعريف الاسماء'!B9) -> امير سرحان كاطع فرهود | AH12: =SUM(D12:AG12) -> 0 | AI12: =(IF(AH12>0,(ROUND((AH12/($AG$2*30))*100,0))/100,"-")) -> - | AJ12: =IF(AH12>=3*$AG$2,"انذار نهائي",IF(AH12>=2*$AG$2,"انذار",IF(AH12>=$AG$2,"تنبيه","")))
A13: 8 | B13: =IF('تعريف الاسماء'!B10<=" "," ",'تعريف الاسماء'!B10) -> امير عبد الهادي عبد الأمير | AH13: =SUM(D13:AG13) -> 0 | AI13: =(IF(AH13>0,(ROUND((AH13/($AG$2*30))*100,0))/100,"-")) -> - | AJ13: =IF(AH13>=3*$AG$2,"انذار نهائي",IF(AH13>=2*$AG$2,"انذار",IF(AH13>=$AG$2,"تنبيه","")))
A14: 9 | B14: =IF('تعريف الاسماء'!B11<=" "," ",'تعريف الاسماء'!B11) -> ايات رزاق جبر جاسم | AH14: =SUM(D14:AG14) -> 0 | AI14: =(IF(AH14>0,(ROUND((AH14/($AG$2*30))*100,0))/100,"-")) -> - | AJ14: =IF(AH14>=3*$AG$2,"انذار نهائي",IF(AH14>=2*$AG$2,"انذار",IF(AH14>=$AG$2,"تنبيه","")))
A15: 10 | B15: =IF('تعريف الاسماء'!B12<=" "," ",'تعريف الاسماء'!B12) -> ايمان فاضل جنابي مزعل | AH15: =SUM(D15:AG15) -> 0 | AI15: =(IF(AH15>0,(ROUND((AH15/($AG$2*30))*100,0))/100,"-")) -> - | AJ15: =IF(AH15>=3*$AG$2,"انذار نهائي",IF(AH15>=2*$AG$2,"انذار",IF(AH15>=$AG$2,"تنبيه","")))
A16: 11 | B16: =IF('تعريف الاسماء'!B13<=" "," ",'تعريف الاسماء'!B13) -> بتول خضير شلال رميح | AH16: =SUM(D16:AG16) -> 0 | AI16: =(IF(AH16>0,(ROUND((AH16/($AG$2*30))*100,0))/100,"-")) -> - | AJ16: =IF(AH16>=3*$AG$2,"انذار نهائي",IF(AH16>=2*$AG$2,"انذار",IF(AH16>=$AG$2,"تنبيه","")))
A17: 12 | B17: =IF('تعريف الاسماء'!B14<=" "," ",'تعريف الاسماء'!B14) -> بتول سعود علكو صباح | AH17: =SUM(D17:AG17) -> 0 | AI17: =(IF(AH17>0,(ROUND((AH17/($AG$2*30))*100,0))/100,"-")) -> - | AJ17: =IF(AH17>=3*$AG$2,"انذار نهائي",IF(AH17>=2*$AG$2,"انذار",IF(AH17>=$AG$2,"تنبيه","")))
... A405: 400 | B405: =IF('تعريف الاسماء'!B402<=" "," ",'تعريف الاسماء'!B402) | AH405: =SUM(D405:AG405) -> 0 | AI405: =(IF(AH405>0,(ROUND((AH405/($AG$2*30))*100,0))/100,"-")) -> - | AJ405: =IF(AH405>=3*$AG$2,"انذار نهائي",IF(AH405>=2*$AG$2,"انذار",IF(AH405>=$AG$2,"تنبيه","")))
D406: 0 | E406: 0 | F406: 0 | AJ406: =IF(AH406>=3*$AG$2,"انذار نهائي",IF(AH406>=2*$AG$2,"انذار",IF(AH406>=$AG$2,"تنبيه","")))
D407: 0 | E407: 0 | F407: 0 | AJ407: =IF(AH407>=3*$AG$2,"انذار نهائي",IF(AH407>=2*$AG$2,"انذار",IF(AH407>=$AG$2,"تنبيه","")))
D408: 0 | E408: 0 | F408: 0 | AJ408: =IF(AH408>=3*$AG$2,"انذار نهائي",IF(AH408>=2*$AG$2,"انذار",IF(AH408>=$AG$2,"تنبيه","")))
D409: 0 | E409: 0 | F409: 0 | AJ409: =IF(AH409>=3*$AG$2,"انذار نهائي",IF(AH409>=2*$AG$2,"انذار",IF(AH409>=$AG$2,"تنبيه","")))
D410: 0 | E410: 0 | F410: 0 | AJ410: =IF(AH410>=3*$AG$2,"انذار نهائي",IF(AH410>=2*$AG$2,"انذار",IF(AH410>=$AG$2,"تنبيه","")))
D411: 0 | E411: 0 | F411: 0 | AJ411: =IF(AH411>=3*$AG$2,"انذار نهائي",IF(AH411>=2*$AG$2,"انذار",IF(AH411>=$AG$2,"تنبيه","")))
D412: 0 | E412: 0 | F412: 0 | AJ412: =IF(AH412>=3*$AG$2,"انذار نهائي",IF(AH412>=2*$AG$2,"انذار",IF(AH412>=$AG$2,"تنبيه","")))
D413: 0 | E413: 0 | F413: 0 | AJ413: =IF(AH413>=3*$AG$2,"انذار نهائي",IF(AH413>=2*$AG$2,"انذار",IF(AH413>=$AG$2,"تنبيه","")))
D414: 0 | E414: 0 | F414: 0 | AJ414: =IF(AH414>=3*$AG$2,"انذار نهائي",IF(AH414>=2*$AG$2,"انذار",IF(AH414>=$AG$2,"تنبيه","")))
D415: 0 | E415: 0 | F415: 0 | AJ415: =IF(AH415>=3*$AG$2,"انذار نهائي",IF(AH415>=2*$AG$2,"انذار",IF(AH415>=$AG$2,"تنبيه","")))
D416: 0 | E416: 0 | F416: 0 | AJ416: =IF(AH416>=3*$AG$2,"انذار نهائي",IF(AH416>=2*$AG$2,"انذار",IF(AH416>=$AG$2,"تنبيه","")))
D417: 0 | E417: 0 | F417: 0 | AJ417: =IF(AH417>=3*$AG$2,"انذار نهائي",IF(AH417>=2*$AG$2,"انذار",IF(AH417>=$AG$2,"تنبيه","")))
... D1120: 0 | E1120: 0 | F1120: 0 | AJ1120: =IF(AH1120>=3*$AG$2,"انذار نهائي",IF(AH1120>=2*$AG$2,"انذار",IF(AH1120>=$AG$2,"تنبيه","")))

Sheet مادة 2
B1: الـقـسـم / | C1: ='تعريف المواد'!C1 -> قسم تقنيات صناعة الأطراف والمساند | U1: المادة | AA1: مدرس المادة | AF1: عدد الساعات
B2: المرحلة / | C2: ='تعريف المواد'!C2 -> الثانية / الكورس الاول / صباحي | U2: ='تعريف المواد'!B6 -> امراض وتشوهات الاطراف | AA2: ='تعريف المواد'!C6 -> د. علي ساجد | AG2: ='تعريف المواد'!D6 -> 2
A3: عمود1 | B3: عمود2 | C3: عمود3 | D3: عمود4 | E3: عمود5 | F3: عمود6 | G3: عمود7 | H3: عمود8 | I3: عمود9 | J3: عمود10 | K3: عمود11 | L3: عمود12 | M3: عمود13 | N3: عمود14 | O3: عمود15 | P3: عمود16 | Q3: عمود17 | R3: عمود18 | S3: عمود19 | T3: عمود20 | U3: عمود21 | V3: عمود22 | W3: عمود23 | X3: عمود24 | Y3: عمود25 | Z3: عمود26 | AA3: عمود27 | AB3: عمود28 | AC3: عمود29 | AD3: عمود30 | AE3: عمود31 | AF3: عمود32 | AG3: عمود33 | AH3: عمود34 | AI3: عمود35 | AJ3: عمود36
AI4: =IF(AH4>0,AH4/($AG$2*30),"-") -> - | AJ4: =IF(AH4>=3*$AG$2,"انذار نهائي",IF(AH4>=2*$AG$2,"انذار",IF(AH4>=$AG$2,"تنبيه","")))
A5: ت | B5: الاسم الثلاثي | C5: الشعبة | D5: الاسبوع 1 | E5: الاسبوع 2 | F5: الاسبوع 3 | G5: الاسبوع 4 | H5: الاسبوع 5 | I5: الاسبوع 6 | J5: الاسبوع 7 | K5: الاسبوع 8 | L5: الاسبوع 9 | M5: الاسبوع 10 | N5: الاسبوع 11 | O5: الاسبوع 12 | P5: الاسبوع 13 | Q5: الاسبوع 14 | R5: الاسبوع 15 | S5: الاسبوع 16 | T5: الاسبوع 17 | U5: الاسبوع 18 | V5: الاسبوع 19 | W5: الاسبوع 20 | X5: الاسبوع 21 | Y5: الاسبوع 22 | Z5: الاسبوع 23 | AA5: الاسبوع 24 | AB5: الاسبوع 25 | AC5: الاسبوع 26 | AD5: الاسبوع 27 | AE5: الاسبوع 28 | AF5: الاسبوع 29 | AG5: الاسبوع 30 | AH5: مجموع الغيابات | AI5: نسبة الغيابات | AJ5: نوع العقوبة
A6: 1 | B6: =IF('تعريف الاسماء'!B3<=" "," ",'تعريف الاسماء'!B3) -> احمدعدي هريبد بريو | C6: =IF('تعريف الاسماء'!C3<=" "," ",'تعريف الاسماء'!C3) | AH6: =SUM(D6:AG6) -> 0 | AI6: =(IF(AH6>0,(ROUND((AH6/($AG$2*30))*100,0))/100,"-")) -> - | AJ6: =IF(AH6>=3*$AG$2,"انذار نهائي",IF(AH6>=2*$AG$2,"انذار",IF(AH6>=$AG$2,"تنبيه","")))
A7: 2 | B7: =IF('تعريف الاسماء'!B4<=" "," ",'تعريف الاسماء'!B4) -> احمد نزار عباس غبن | C7: =IF('تعريف الاسماء'!C4<=" "," ",'تعريف الاسماء'!C4) | AH7: =SUM(D7:AG7) -> 0 | AI7: =(IF(AH7>0,(ROUND((AH7/($AG$2*30))*100,0))/100,"-")) -> - | AJ7: =IF(AH7>=3*$AG$2,"انذار نهائي",IF(AH7>=2*$AG$2,"انذار",IF(AH7>=$AG$2,"تنبيه","")))
A8: 3 | B8: =IF('تعريف الاسماء'!B5<=" "," ",'تعريف الاسماء'!B5) -> استبرق مرتضى عبد شهيد | C8: =IF('تعريف الاسماء'!C5<=" "," ",'تعريف الاسماء'!C5) | AH8: =SUM(D8:AG8) -> 0 | AI8: =(IF(AH8>0,(ROUND((AH8/($AG$2*30))*100,0))/100,"-")) -> - | AJ8: =IF(AH8>=3*$AG$2,"انذار نهائي",IF(AH8>=2*$AG$2,"انذار",IF(AH8>=$AG$2,"تنبيه","")))
A9: 4 | B9: =IF('تعريف الاسماء'!B6<=" "," ",'تعريف الاسماء'!B6) -> اسراء عمارحاكم وحيد | C9: =IF('تعريف الاسماء'!C6<=" "," ",'تعريف الاسماء'!C6) | AH9: =SUM(D9:AG9) -> 0 | AI9: =(IF(AH9>0,(ROUND((AH9/($AG$2*30))*100,0))/100,"-")) -> - | AJ9: =IF(AH9>=3*$AG$2,"انذار نهائي",IF(AH9>=2*$AG$2,"انذار",IF(AH9>=$AG$2,"تنبيه","")))
A10: 5 | B10: =IF('تعريف الاسماء'!B7<=" "," ",'تعريف الاسماء'!B7) -> افراح نصير علي عودة | C10: =IF('تعريف الاسماء'!C7<=" "," ",'تعريف الاسماء'!C7) | AH10: =SUM(D10:AG10) -> 0 | AI10: =(IF(AH10>0,(ROUND((AH10/($AG$2*30))*100,0))/100,"-")) -> - | AJ10: =IF(AH10>=3*$AG$2,"انذار نهائي",IF(AH10>=2*$AG$2,"انذار",IF(AH10>=$AG$2,"تنبيه","")))
A11: 6 | B11: =IF('تعريف الاسماء'!B8<=" "," ",'تعريف الاسماء'!B8) -> امجد نعيم داود سلمان | C11: =IF('تعريف الاسماء'!C8<=" "," ",'تعريف الاسماء'!C8) | AH11: =SUM(D11:AG11) -> 0 | AI11: =(IF(AH11>0,(ROUND((AH11/($AG$2*30))*100,0))/100,"-")) -> - | AJ11: =IF(AH11>=3*$AG$2,"انذار نهائي",IF(AH11>=2*$AG$2,"انذار",IF(AH11>=$AG$2,"تنبيه","")))
A12: 7 | B12: =IF('تعريف الاسماء'!B9<=" "," ",'تعريف الاسماء'!B9) -> امير سرحان كاطع فرهود | C12: =IF('تعريف الاسماء'!C9<=" "," ",'تعريف الاسماء'!C9) | AH12: =SUM(D12:AG12) -> 0 | AI12: =(IF(AH12>0,(ROUND((AH12/($AG$2*30))*100,0))/100,"-")) -> - | AJ12: =IF(AH12>=3*$AG$2,"انذار نهائي",IF(AH12>=2*$AG$2,"انذار",IF(AH12>=$AG$2,"تنبيه","")))
A13: 8 | B13: =IF('تعريف الاسماء'!B10<=" "," ",'تعريف الاسماء'!B10) -> امير عبد الهادي عبد الأمير | C13: =IF('تعريف الاسماء'!C10<=" "," ",'تعريف الاسماء'!C10) | AH13: =SUM(D13:AG13) -> 0 | AI13: =(IF(AH13>0,(ROUND((AH13/($AG$2*30))*100,0))/100,"-")) -> - | AJ13: =IF(AH13>=3*$AG$2,"انذار نهائي",IF(AH13>=2*$AG$2,"انذار",IF(AH13>=$AG$2,"تنبيه","")))
A14: 9 | B14: =IF('تعريف الاسماء'!B11<=" "," ",'تعريف الاسماء'!B11) -> ايات رزاق جبر جاسم | C14: =IF('تعريف الاسماء'!C11<=" "," ",'تعريف الاسماء'!C11) | AH14: =SUM(D14:AG14) -> 0 | AI14: =(IF(AH14>0,(ROUND((AH14/($AG$2*30))*100,0))/100,"-")) -> - | AJ14: =IF(AH14>=3*$AG$2,"انذار نهائي",IF(AH14>=2*$AG$2,"انذار",IF(AH14>=$AG$2,"تنبيه","")))
A15: 10 | B15: =IF('تعريف الاسماء'!B12<=" "," ",'تعريف الاسماء'!B12) -> ايمان فاضل جنابي مزعل | C15: =IF('تعريف الاسماء'!C12<=" "," ",'تعريف الاسماء'!C12) | AH15: =SUM(D15:AG15) -> 0 | AI15: =(IF(AH15>0,(ROUND((AH15/($AG$2*30))*100,0))/100,"-")) -> - | AJ15: =IF(AH15>=3*$AG$2,"انذار نهائي",IF(AH15>=2*$AG$2,"انذار",IF(AH15>=$AG$2,"تنبيه","")))
A16: 11 | B16: =IF('تعريف الاسماء'!B13<=" "," ",'تعريف الاسماء'!B13) -> بتول خضير شلال رميح | C16: =IF('تعريف الاسماء'!C13<=" "," ",'تعريف الاسماء'!C13) | AH16: =SUM(D16:AG16) -> 0 | AI16: =(IF(AH16>0,(ROUND((AH16/($AG$2*30))*100,0))/100,"-")) -> - | AJ16: =IF(AH16>=3*$AG$2,"انذار نهائي",IF(AH16>=2*$AG$2,"انذار",IF(AH16>=$AG$2,"تنبيه","")))
A17: 12 | B17: =IF('تعريف الاسماء'!B14<=" "," ",'تعريف الاسماء'!B14) -> بتول سعود علكو صباح | C17: =IF('تعريف الاسماء'!C14<=" "," ",'تعريف الاسماء'!C14) | AH17: =SUM(D17:AG17) -> 0 | AI17: =(IF(AH17>0,(ROUND((AH17/($AG$2*30))*100,0))/100,"-")) -> - | AJ17: =IF(AH17>=3*$AG$2,"انذار نهائي",IF(AH17>=2*$AG$2,"انذار",IF(AH17>=$AG$2,"تنبيه","")))
... A405: 400 | B405: =IF('تعريف الاسماء'!B402<=" "," ",'تعريف الاسماء'!B402) | C405: =IF('تعريف الاسماء'!C402<=" "," ",'تعريف الاسماء'!C402) | AH405: =SUM(D405:AG405) -> 0 | AI405: =(IF(AH405>0,(ROUND((AH405/($AG$2*30))*100,0))/100,"-")) -> - | AJ405: =IF(AH405>=3*$AG$2,"انذار نهائي",IF(AH405>=2*$AG$2,"انذار",IF(AH405>=$AG$2,"تنبيه","")))
D406: 0 | E406: 0 | F406: 0 | AJ406: =IF(AH406>=3*$AG$2,"انذار نهائي",IF(AH406>=2*$AG$2,"انذار",IF(AH406>=$AG$2,"تنبيه","")))
D407: 0 | E407: 0 | F407: 0 | AJ407: =IF(AH407>=3*$AG$2,"انذار نهائي",IF(AH407>=2*$AG$2,"انذار",IF(AH407>=$AG$2,"تنبيه","")))
D408: 0 | E408: 0 | F408: 0 | AJ408: =IF(AH408>=3*$AG$2,"انذار نهائي",IF(AH408>=2*$AG$2,"انذار",IF(AH408>=$AG$2,"تنبيه","")))
D409: 0 | E409: 0 | F409: 0 | AJ409: =IF(AH409>=3*$AG$2,"انذار نهائي",IF(AH409>=2*$AG$2,"انذار",IF(AH409>=$AG$2,"تنبيه","")))
D410: 0 | E410: 0 | F410: 0 | AJ410: =IF(AH410>=3*$AG$2,"انذار نهائي",IF(AH410>=2*$AG$2,"انذار",IF(AH410>=$AG$2,"تنبيه","")))
D411: 0 | E411: 0 | F411: 0 | AJ411: =IF(AH411>=3*$AG$2,"انذار نهائي",IF(AH411>=2*$AG$2,"انذار",IF(AH411>=$AG$2,"تنبيه","")))
D412: 0 | E412: 0 | F412: 0 | AJ412: =IF(AH412>=3*$AG$2,"انذار نهائي",IF(AH412>=2*$AG$2,"انذار",IF(AH412>=$AG$2,"تنبيه","")))
D413: 0 | E413: 0 | F413: 0 | AJ413: =IF(AH413>=3*$AG$2,"انذار نهائي",IF(AH413>=2*$AG$2,"انذار",IF(AH413>=$AG$2,"تنبيه","")))
D414: 0 | E414: 0 | F414: 0 | AJ414: =IF(AH414>=3*$AG$2,"انذار نهائي",IF(AH414>=2*$AG$2,"انذار",IF(AH414>=$AG$2,"تنبيه","")))
D415: 0 | E415: 0 | F415: 0 | AJ415: =IF(AH415>=3*$AG$2,"انذار نهائي",IF(AH415>=2*$AG$2,"انذار",IF(AH415>=$AG$2,"تنبيه","")))
D416: 0 | E416: 0 | F416: 0 | AJ416: =IF(AH416>=3*$AG$2,"انذار نهائي",IF(AH416>=2*$AG$2,"انذار",IF(AH416>=$AG$2,"تنبيه","")))
D417: 0 | E417: 0 | F417: 0 | AJ417: =IF(AH417>=3*$AG$2,"انذار نهائي",IF(AH417>=2*$AG$2,"انذار",IF(AH417>=$AG$2,"تنبيه","")))
... D1120: 0 | E1120: 0 | F1120: 0 | AJ1120: =IF(AH1120>=3*$AG$2,"انذار نهائي",IF(AH1120>=2*$AG$2,"انذار",IF(AH1120>=$AG$2,"تنبيه","")))

Sheet مادة 3
B1: الـقـسـم / | C1: ='تعريف المواد'!C1 -> قسم تقنيات صناعة الأطراف والمساند | U1: المادة | AA1: مدرس المادة | AF1: عدد الساعات
B2: المرحلة / | C2: ='تعريف المواد'!C2 -> الثانية / الكورس الاول / صباحي | U2: ='تعريف المواد'!B7 -> بايو ميكانيك | AA2: ='تعريف المواد'!C7 -> م.م صالح مطشر | AG2: ='تعريف المواد'!D7 -> 3
A3: عمود1 | B3: عمود2 | C3: عمود3 | D3: عمود10 | E3: عمود11 | F3: عمود12 | G3: عمود13 | H3: عمود14 | I3: عمود15 | J3: عمود16 | K3: عمود17 | L3: عمود18 | M3: عمود19 | N3: عمود20 | O3: عمود21 | P3: عمود22 | Q3: عمود23 | R3: عمود24 | S3: عمود25 | T3: عمود26 | U3: عمود27 | V3: عمود28 | W3: عمود29 | X3: عمود30 | Y3: عمود31 | Z3: عمود32 | AA3: عمود33 | AB3: عمود34 | AC3: عمود35 | AD3: عمود36
D4: 26|10 | E4: 2|11 | F4: 9|11 | G4: 16|11 | AC4: =IF(AB4>0,AB4/($AG$2*30),"-") -> - | AD4: =IF(AB4>=3*$AG$2,"انذار نهائي",IF(AB4>=2*$AG$2,"انذار",IF(AB4>=$AG$2,"تنبيه","")))
A5: ت | B5: الاسم الثلاثي | C5: الشعبة | D5: الأسبوع 1 | E5: الأسبوع 2 | F5: الأسبوع 3 | G5: الاسبوع 4 | H5: الأسبوع 5 | I5: الاسبوع 12 | J5: الاسبوع 13 | K5: الاسبوع 14 | L5: الاسبوع 15 | M5: الاسبوع 16 | N5: الاسبوع 17 | O5: الاسبوع 18 | P5: الاسبوع 19 | Q5: الاسبوع 20 | R5: الاسبوع 21 | S5: الاسبوع 22 | T5: الاسبوع 23 | U5: الاسبوع 24 | V5: الاسبوع 25 | W5: الاسبوع 26 | X5: الاسبوع 27 | Y5: الاسبوع 28 | Z5: الاسبوع 29 | AA5: الاسبوع 30 | AB5: مجموع الغيابات | AC5: نسبة الغيابات | AD5: نوع العقوبة
A6: 1 | B6: =IF('تعريف الاسماء'!B3<=" "," ",'تعريف الاسماء'!B3) -> احمدعدي هريبد بريو | C6: =IF('تعريف الاسماء'!C3<=" "," ",'تعريف الاسماء'!C3) | AB6: =SUM(D6:AA6) -> 0 | AC6: =(IF(AB6>0,(ROUND((AB6/($AG$2*30))*100,0))/100,"-")) -> - | AD6: =IF(AB6>=3*$AG$2,"انذار نهائي",IF(AB6>=2*$AG$2,"انذار",IF(AB6>=$AG$2,"تنبيه","")))
A7: 2 | B7: =IF('تعريف الاسماء'!B4<=" "," ",'تعريف الاسماء'!B4) -> احمد نزار عباس غبن | C7: =IF('تعريف الاسماء'!C4<=" "," ",'تعريف الاسماء'!C4) | AB7: =SUM(D7:AA7) -> 0 | AC7: =(IF(AB7>0,(ROUND((AB7/($AG$2*30))*100,0))/100,"-")) -> - | AD7: =IF(AB7>=3*$AG$2,"انذار نهائي",IF(AB7>=2*$AG$2,"انذار",IF(AB7>=$AG$2,"تنبيه","")))
A8: 3 | B8: =IF('تعريف الاسماء'!B5<=" "," ",'تعريف الاسماء'!B5) -> استبرق مرتضى عبد شهيد | C8: =IF('تعريف الاسماء'!C5<=" "," ",'تعريف الاسماء'!C5) | AB8: =SUM(D8:AA8) -> 0 | AC8: =(IF(AB8>0,(ROUND((AB8/($AG$2*30))*100,0))/100,"-")) -> - | AD8: =IF(AB8>=3*$AG$2,"انذار نهائي",IF(AB8>=2*$AG$2,"انذار",IF(AB8>=$AG$2,"تنبيه","")))
A9: 4 | B9: =IF('تعريف الاسماء'!B6<=" "," ",'تعريف الاسماء'!B6) -> اسراء عمارحاكم وحيد | C9: =IF('تعريف الاسماء'!C6<=" "," ",'تعريف الاسماء'!C6) | AB9: =SUM(D9:AA9) -> 0 | AC9: =(IF(AB9>0,(ROUND((AB9/($AG$2*30))*100,0))/100,"-")) -> - | AD9: =IF(AB9>=3*$AG$2,"انذار نهائي",IF(AB9>=2*$AG$2,"انذار",IF(AB9>=$AG$2,"تنبيه","")))
A10: 5 | B10: =IF('تعريف الاسماء'!B7<=" "," ",'تعريف الاسماء'!B7) -> افراح نصير علي عودة | C10: =IF('تعريف الاسماء'!C7<=" "," ",'تعريف الاسماء'!C7) | AB10: =SUM(D10:AA10) -> 0 | AC10: =(IF(AB10>0,(ROUND((AB10/($AG$2*30))*100,0))/100,"-")) -> - | AD10: =IF(AB10>=3*$AG$2,"انذار نهائي",IF(AB10>=2*$AG$2,"انذار",IF(AB10>=$AG$2,"تنبيه","")))
A11: 6 | B11: =IF('تعريف الاسماء'!B8<=" "," ",'تعريف الاسماء'!B8) -> امجد نعيم داود سلمان | C11: =IF('تعريف الاسماء'!C8<=" "," ",'تعريف الاسماء'!C8) | AB11: =SUM(D11:AA11) -> 0 | AC11: =(IF(AB11>0,(ROUND((AB11/($AG$2*30))*100,0))/100,"-")) -> - | AD11: =IF(AB11>=3*$AG$2,"انذار نهائي",IF(AB11>=2*$AG$2,"انذار",IF(AB11>=$AG$2,"تنبيه","")))
A12: 7 | B12: =IF('تعريف الاسماء'!B9<=" "," ",'تعريف الاسماء'!B9) -> امير سرحان كاطع فرهود | C12: =IF('تعريف الاسماء'!C9<=" "," ",'تعريف الاسماء'!C9) | AB12: =SUM(D12:AA12) -> 0 | AC12: =(IF(AB12>0,(ROUND((AB12/($AG$2*30))*100,0))/100,"-")) -> - | AD12: =IF(AB12>=3*$AG$2,"انذار نهائي",IF(AB12>=2*$AG$2,"انذار",IF(AB12>=$AG$2,"تنبيه","")))
A13: 8 | B13: =IF('تعريف الاسماء'!B10<=" "," ",'تعريف الاسماء'!B10) -> امير عبد الهادي عبد الأمير | C13: =IF('تعريف الاسماء'!C10<=" "," ",'تعريف الاسماء'!C10) | AB13: =SUM(D13:AA13) -> 0 | AC13: =(IF(AB13>0,(ROUND((AB13/($AG$2*30))*100,0))/100,"-")) -> - | AD13: =IF(AB13>=3*$AG$2,"انذار نهائي",IF(AB13>=2*$AG$2,"انذار",IF(AB13>=$AG$2,"تنبيه","")))
A14: 9 | B14: =IF('تعريف الاسماء'!B11<=" "," ",'تعريف الاسماء'!B11) -> ايات رزاق جبر جاسم | C14: =IF('تعريف الاسماء'!C11<=" "," ",'تعريف الاسماء'!C11) | AB14: =SUM(D14:AA14) -> 0 | AC14: =(IF(AB14>0,(ROUND((AB14/($AG$2*30))*100,0))/100,"-")) -> - | AD14: =IF(AB14>=3*$AG$2,"انذار نهائي",IF(AB14>=2*$AG$2,"انذار",IF(AB14>=$AG$2,"تنبيه","")))
A15: 10 | B15: =IF('تعريف الاسماء'!B12<=" "," ",'تعريف الاسماء'!B12) -> ايمان فاضل جنابي مزعل | C15: =IF('تعريف الاسماء'!C12<=" "," ",'تعريف الاسماء'!C12) | AB15: =SUM(D15:AA15) -> 0 | AC15: =(IF(AB15>0,(ROUND((AB15/($AG$2*30))*100,0))/100,"-")) -> - | AD15: =IF(AB15>=3*$AG$2,"انذار نهائي",IF(AB15>=2*$AG$2,"انذار",IF(AB15>=$AG$2,"تنبيه","")))
A16: 11 | B16: =IF('تعريف الاسماء'!B13<=" "," ",'تعريف الاسماء'!B13) -> بتول خضير شلال رميح | C16: =IF('تعريف الاسماء'!C13<=" "," ",'تعريف الاسماء'!C13) | AB16: =SUM(D16:AA16) -> 0 | AC16: =(IF(AB16>0,(ROUND((AB16/($AG$2*30))*100,0))/100,"-")) -> - | AD16: =IF(AB16>=3*$AG$2,"انذار نهائي",IF(AB16>=2*$AG$2,"انذار",IF(AB16>=$AG$2,"تنبيه","")))
A17: 12 | B17: =IF('تعريف الاسماء'!B14<=" "," ",'تعريف الاسماء'!B14) -> بتول سعود علكو صباح | C17: =IF('تعريف الاسماء'!C14<=" "," ",'تعريف الاسماء'!C14) | AB17: =SUM(D17:AA17) -> 0 | AC17: =(IF(AB17>0,(ROUND((AB17/($AG$2*30))*100,0))/100,"-")) -> - | AD17: =IF(AB17>=3*$AG$2,"انذار نهائي",IF(AB17>=2*$AG$2,"انذار",IF(AB17>=$AG$2,"تنبيه","")))
... A405: 400 | B405: =IF('تعريف الاسماء'!B402<=" "," ",'تعريف الاسماء'!B402) | C405: =IF('تعريف الاسماء'!C402<=" "," ",'تعريف الاسماء'!C402) | AB405: =SUM(D405:AA405) -> 0 | AC405: =(IF(AB405>0,(ROUND((AB405/($AG$2*30))*100,0))/100,"-")) -> - | AD405: =IF(AB405>=3*$AG$2,"انذار نهائي",IF(AB405>=2*$AG$2,"انذار",IF(AB405>=$AG$2,"تنبيه","")))
D406: 0 | E406: 0 | F406: 0 | AJ406: =IF(AH406>=3*$AG$2,"انذار نهائي",IF(AH406>=2*$AG$2,"انذار",IF(AH406>=$AG$2,"تنبيه","")))
D407: 0 | E407: 0 | F407: 0 | AJ407: =IF(AH407>=3*$AG$2,"انذار نهائي",IF(AH407>=2*$AG$2,"انذار",IF(AH407>=$AG$2,"تنبيه","")))
D408: 0 | E408: 0 | F408: 0 | AJ408: =IF(AH408>=3*$AG$2,"انذار نهائي",IF(AH408>=2*$AG$2,"انذار",IF(AH408>=$AG$2,"تنبيه","")))
D409: 0 | E409: 0 | F409: 0 | AJ409: =IF(AH409>=3*$AG$2,"انذار نهائي",IF(AH409>=2*$AG$2,"انذار",IF(AH409>=$AG$2,"تنبيه","")))
D410: 0 | E410: 0 | F410: 0 | AJ410: =IF(AH410>=3*$AG$2,"انذار نهائي",IF(AH410>=2*$AG$2,"انذار",IF(AH410>=$AG$2,"تنبيه","")))
D411: 0 | E411: 0 | F411: 0 | AJ411: =IF(AH411>=3*$AG$2,"انذار نهائي",IF(AH411>=2*$AG$2,"انذار",IF(AH411>=$AG$2,"تنبيه","")))
D412: 0 | E412: 0 | F412: 0 | AJ412: =IF(AH412>=3*$AG$2,"انذار نهائي",IF(AH412>=2*$AG$2,"انذار",IF(AH412>=$AG$2,"تنبيه","")))
D413: 0 | E413: 0 | F413: 0 | AJ413: =IF(AH413>=3*$AG$2,"انذار نهائي",IF(AH413>=2*$AG$2,"انذار",IF(AH413>=$AG$2,"تنبيه","")))
D414: 0 | E414: 0 | F414: 0 | AJ414: =IF(AH414>=3*$AG$2,"انذار نهائي",IF(AH414>=2*$AG$2,"انذار",IF(AH414>=$AG$2,"تنبيه","")))
D415: 0 | E415: 0 | F415: 0 | AJ415: =IF(AH415>=3*$AG$2,"انذار نهائي",IF(AH415>=2*$AG$2,"انذار",IF(AH415>=$AG$2,"تنبيه","")))
D416: 0 | E416: 0 | F416: 0 | AJ416: =IF(AH416>=3*$AG$2,"انذار نهائي",IF(AH416>=2*$AG$2,"انذار",IF(AH416>=$AG$2,"تنبيه","")))
D417: 0 | E417: 0 | F417: 0 | AJ417: =IF(AH417>=3*$AG$2,"انذار نهائي",IF(AH417>=2*$AG$2,"انذار",IF(AH417>=$AG$2,"تنبيه","")))
... D1120: 0 | E1120: 0 | F1120: 0 | AJ1120: =IF(AH1120>=3*$AG$2,"انذار نهائي",IF(AH1120>=2*$AG$2,"انذار",IF(AH1120>=$AG$2,"تنبيه","")))

Sheet مادة 4
B1: الـقـسـم / | C1: ='تعريف المواد'!C1 -> قسم تقنيات صناعة الأطراف والمساند | U1: المادة | AA1: مدرس المادة | AF1: عدد الساعات
B2: المرحلة / | C2: ='تعريف المواد'!C2 -> الثانية / الكورس الاول / صباحي | U2: ='تعريف المواد'!B8 -> تشريح الأطراف العليا | AA2: ='تعريف المواد'!C8 -> م.م براء جليل سعيد | AG2: ='تعريف المواد'!D8 -> 3
A3: عمود1 | B3: عمود2 | C3: عمود3 | D3: عمود4 | E3: عمود5 | F3: عمود6 | G3: عمود7 | H3: عمود8 | I3: عمود9 | J3: عمود10 | K3: عمود11 | L3: عمود12 | M3: عمود13 | N3: عمود14 | O3: عمود15 | P3: عمود16 | Q3: عمود17 | R3: عمود18 | S3: عمود19 | T3: عمود20 | U3: عمود21 | V3: عمود22 | W3: عمود23 | X3: عمود24 | Y3: عمود25 | Z3: عمود26 | AA3: عمود27 | AB3: عمود28 | AC3: عمود29 | AD3: عمود30 | AE3: عمود31 | AF3: عمود32 | AG3: عمود33 | AH3: عمود34 | AI3: عمود35 | AJ3: عمود36
AI4: =IF(AH4>0,AH4/($AG$2*30),"-") -> - | AJ4: =IF(AH4>=3*$AG$2,"انذار نهائي",IF(AH4>=2*$AG$2,"انذار",IF(AH4>=$AG$2,"تنبيه","")))
A5: ت | B5: الاسم الثلاثي | C5: الشعبة | D5: الاسبوع 1 | E5: الاسبوع 2 | F5: الاسبوع 3 | G5: الاسبوع 4 | H5: الاسبوع 5 | I5: الاسبوع 6 | J5: الاسبوع 7 | K5: الاسبوع 8 | L5: الاسبوع 9 | M5: الاسبوع 10 | N5: الاسبوع 11 | O5: الاسبوع 12 | P5: الاسبوع 13 | Q5: الاسبوع 14 | R5: الاسبوع 15 | S5: الاسبوع 16 | T5: الاسبوع 17 | U5: الاسبوع 18 | V5: الاسبوع 19 | W5: الاسبوع 20 | X5: الاسبوع 21 | Y5: الاسبوع 22 | Z5: الاسبوع 23 | AA5: الاسبوع 24 | AB5: الاسبوع 25 | AC5: الاسبوع 26 | AD5: الاسبوع 27 | AE5: الاسبوع 28 | AF5: الاسبوع 29 | AG5: الاسبوع 30 | AH5: مجموع الغيابات | AI5: نسبة الغيابات | AJ5: نوع العقوبة
A6: 1 | B6: =IF('تعريف الاسماء'!B3<=" "," ",'تعريف الاسماء'!B3) -> احمدعدي هريبد بريو | C6: =IF('تعريف الاسماء'!C3<=" "," ",'تعريف الاسماء'!C3) | AH6: =SUM(D6:AG6) -> 0 | AI6: =(IF(AH6>0,(ROUND((AH6/($AG$2*30))*100,0))/100,"-")) -> - | AJ6: =IF(AH6>=3*$AG$2,"انذار نهائي",IF(AH6>=2*$AG$2,"انذار",IF(AH6>=$AG$2,"تنبيه","")))
A7: 2 | B7: =IF('تعريف الاسماء'!B4<=" "," ",'تعريف الاسماء'!B4) -> احمد نزار عباس غبن | C7: =IF('تعريف الاسماء'!C4<=" "," ",'تعريف الاسماء'!C4) | AH7: =SUM(D7:AG7) -> 0 | AI7: =(IF(AH7>0,(ROUND((AH7/($AG$2*30))*100,0))/100,"-")) -> - | AJ7: =IF(AH7>=3*$AG$2,"انذار نهائي",IF(AH7>=2*$AG$2,"انذار",IF(AH7>=$AG$2,"تنبيه","")))
A8: 3 | B8: =IF('تعريف الاسماء'!B5<=" "," ",'تعريف الاسماء'!B5) -> استبرق مرتضى عبد شهيد | C8: =IF('تعريف الاسماء'!C5<=" "," ",'تعريف الاسماء'!C5) | AH8: =SUM(D8:AG8) -> 0 | AI8: =(IF(AH8>0,(ROUND((AH8/($AG$2*30))*100,0))/100,"-")) -> - | AJ8: =IF(AH8>=3*$AG$2,"انذار نهائي",IF(AH8>=2*$AG$2,"انذار",IF(AH8>=$AG$2,"تنبيه","")))
A9: 4 | B9: =IF('تعريف الاسماء'!B6<=" "," ",'تعريف الاسماء'!B6) -> اسراء عمارحاكم وحيد | C9: =IF('تعريف الاسماء'!C6<=" "," ",'تعريف الاسماء'!C6) | AH9: =SUM(D9:AG9) -> 0 | AI9: =(IF(AH9>0,(ROUND((AH9/($AG$2*30))*100,0))/100,"-")) -> - | AJ9: =IF(AH9>=3*$AG$2,"انذار نهائي",IF(AH9>=2*$AG$2,"انذار",IF(AH9>=$AG$2,"تنبيه","")))
A10: 5 | B10: =IF('تعريف الاسماء'!B7<=" "," ",'تعريف الاسماء'!B7) -> افراح نصير علي عودة | C10: =IF('تعريف الاسماء'!C7<=" "," ",'تعريف الاسماء'!C7) | AH10: =SUM(D10:AG10) -> 0 | AI10: =(IF(AH10>0,(ROUND((AH10/($AG$2*30))*100,0))/100,"-")) -> - | AJ10: =IF(AH10>=3*$AG$2,"انذار نهائي",IF(AH10>=2*$AG$2,"انذار",IF(AH10>=$AG$2,"تنبيه","")))
A11: 6 | B11: =IF('تعريف الاسماء'!B8<=" "," ",'تعريف الاسماء'!B8) -> امجد نعيم داود سلمان | C11: =IF('تعريف الاسماء'!C8<=" "," ",'تعريف الاسماء'!C8) | AH11: =SUM(D11:AG11) -> 0 | AI11: =(IF(AH11>0,(ROUND((AH11/($AG$2*30))*100,0))/100,"-")) -> - | AJ11: =IF(AH11>=3*$AG$2,"انذار نهائي",IF(AH11>=2*$AG$2,"انذار",IF(AH11>=$AG$2,"تنبيه","")))
A12: 7 | B12: =IF('تعريف الاسماء'!B9<=" "," ",'تعريف الاسماء'!B9) -> امير سرحان كاطع فرهود | C12: =IF('تعريف الاسماء'!C9<=" "," ",'تعريف الاسماء'!C9) | AH12: =SUM(D12:AG12) -> 0 | AI12: =(IF(AH12>0,(ROUND((AH12/($AG$2*30))*100,0))/100,"-")) -> - | AJ12: =IF(AH12>=3*$AG$2,"انذار نهائي",IF(AH12>=2*$AG$2,"انذار",IF(AH12>=$AG$2,"تنبيه","")))
A13: 8 | B13: =IF('تعريف الاسماء'!B10<=" "," ",'تعريف الاسماء'!B10) -> امير عبد الهادي عبد الأمير | C13: =IF('تعريف الاسماء'!C10<=" "," ",'تعريف الاسماء'!C10) | AH13: =SUM(D13:AG13) -> 0 | AI13: =(IF(AH13>0,(ROUND((AH13/($AG$2*30))*100,0))/100,"-")) -> - | AJ13: =IF(AH13>=3*$AG$2,"انذار نهائي",IF(AH13>=2*$AG$2,"انذار",IF(AH13>=$AG$2,"تنبيه","")))
A14: 9 | B14: =IF('تعريف الاسماء'!B11<=" "," ",'تعريف الاسماء'!B11) -> ايات رزاق جبر جاسم | C14: =IF('تعريف الاسماء'!C11<=" "," ",'تعريف الاسماء'!C11) | AH14: =SUM(D14:AG14) -> 0 | AI14: =(IF(AH14>0,(ROUND((AH14/($AG$2*30))*100,0))/100,"-")) -> - | AJ14: =IF(AH14>=3*$AG$2,"انذار نهائي",IF(AH14>=2*$AG$2,"انذار",IF(AH14>=$AG$2,"تنبيه","")))
A15: 10 | B15: =IF('تعريف الاسماء'!B12<=" "," ",'تعريف الاسماء'!B12) -> ايمان فاضل جنابي مزعل | C15: =IF('تعريف الاسماء'!C12<=" "," ",'تعريف الاسماء'!C12) | AH15: =SUM(D15:AG15) -> 0 | AI15: =(IF(AH15>0,(ROUND((AH15/($AG$2*30))*100,0))/100,"-")) -> - | AJ15: =IF(AH15>=3*$AG$2,"انذار نهائي",IF(AH15>=2*$AG$2,"انذار",IF(AH15>=$AG$2,"تنبيه","")))
A16: 11 | B16: =IF('تعريف الاسماء'!B13<=" "," ",'تعريف الاسماء'!B13) -> بتول خضير شلال رميح | C16: =IF('تعريف الاسماء'!C13<=" "," ",'تعريف الاسماء'!C13) | AH16: =SUM(D16:AG16) -> 0 | AI16: =(IF(AH16>0,(ROUND((AH16/($AG$2*30))*100,0))/100,"-")) -> - | AJ16: =IF(AH16>=3*$AG$2,"انذار نهائي",IF(AH16>=2*$AG$2,"انذار",IF(AH16>=$AG$2,"تنبيه","")))
A17: 12 | B17: =IF('تعريف الاسماء'!B14<=" "," ",'تعريف الاسماء'!B14) -> بتول سعود علكو صباح | C17: =IF('تعريف الاسماء'!C14<=" "," ",'تعريف الاسماء'!C14) | AH17: =SUM(D17:AG17) -> 0 | AI17: =(IF(AH17>0,(ROUND((AH17/($AG$2*30))*100,0))/100,"-")) -> - | AJ17: =IF(AH17>=3*$AG$2,"انذار نهائي",IF(AH17>=2*$AG$2,"انذار",IF(AH17>=$AG$2,"تنبيه","")))
... A405: 400 | B405: =IF('تعريف الاسماء'!B402<=" "," ",'تعريف الاسماء'!B402) | C405: =IF('تعريف الاسماء'!C402<=" "," ",'تعريف الاسماء'!C402) | AH405: =SUM(D405:AG405) -> 0 | AI405: =(IF(AH405>0,(ROUND((AH405/($AG$2*30))*100,0))/100,"-")) -> - | AJ405: =IF(AH405>=3*$AG$2,"انذار نهائي",IF(AH405>=2*$AG$2,"انذار",IF(AH405>=$AG$2,"تنبيه","")))
D406: 0 | E406: 0 | F406: 0 | AJ406: =IF(AH406>=3*$AG$2,"انذار نهائي",IF(AH406>=2*$AG$2,"انذار",IF(AH406>=$AG$2,"تنبيه","")))
D407: 0 | E407: 0 | F407: 0 | AJ407: =IF(AH407>=3*$AG$2,"انذار نهائي",IF(AH407>=2*$AG$2,"انذار",IF(AH407>=$AG$2,"تنبيه","")))
D408: 0 | E408: 0 | F408: 0 | AJ408: =IF(AH408>=3*$AG$2,"انذار نهائي",IF(AH408>=2*$AG$2,"انذار",IF(AH408>=$AG$2,"تنبيه","")))
D409: 0 | E409: 0 | F409: 0 | AJ409: =IF(AH409>=3*$AG$2,"انذار نهائي",IF(AH409>=2*$AG$2,"انذار",IF(AH409>=$AG$2,"تنبيه","")))
D410: 0 | E410: 0 | F410: 0 | AJ410: =IF(AH410>=3*$AG$2,"انذار نهائي",IF(AH410>=2*$AG$2,"انذار",IF(AH410>=$AG$2,"تنبيه","")))
D411: 0 | E411: 0 | F411: 0 | AJ411: =IF(AH411>=3*$AG$2,"انذار نهائي",IF(AH411>=2*$AG$2,"انذار",IF(AH411>=$AG$2,"تنبيه","")))
D412: 0 | E412: 0 | F412: 0 | AJ412: =IF(AH412>=3*$AG$2,"انذار نهائي",IF(AH412>=2*$AG$2,"انذار",IF(AH412>=$AG$2,"تنبيه","")))
D413: 0 | E413: 0 | F413: 0 | AJ413: =IF(AH413>=3*$AG$2,"انذار نهائي",IF(AH413>=2*$AG$2,"انذار",IF(AH413>=$AG$2,"تنبيه","")))
D414: 0 | E414: 0 | F414: 0 | AJ414: =IF(AH414>=3*$AG$2,"انذار نهائي",IF(AH414>=2*$AG$2,"انذار",IF(AH414>=$AG$2,"تنبيه","")))
D415: 0 | E415: 0 | F415: 0 | AJ415: =IF(AH415>=3*$AG$2,"انذار نهائي",IF(AH415>=2*$AG$2,"انذار",IF(AH415>=$AG$2,"تنبيه","")))
D416: 0 | E416: 0 | F416: 0 | AJ416: =IF(AH416>=3*$AG$2,"انذار نهائي",IF(AH416>=2*$AG$2,"انذار",IF(AH416>=$AG$2,"تنبيه","")))
D417: 0 | E417: 0 | F417: 0 | AJ417: =IF(AH417>=3*$AG$2,"انذار نهائي",IF(AH417>=2*$AG$2,"انذار",IF(AH417>=$AG$2,"تنبيه","")))
... D1120: 0 | E1120: 0 | F1120: 0 | AJ1120: =IF(AH1120>=3*$AG$2,"انذار نهائي",IF(AH1120>=2*$AG$2,"انذار",IF(AH1120>=$AG$2,"تنبيه","")))

Sheet مادة 5
B1: الـقـسـم / | C1: ='تعريف المواد'!C1 -> قسم تقنيات صناعة الأطراف والمساند | U1: المادة | AA1: مدرس المادة | AF1: عدد الساعات
B2: المرحلة / | C2: ='تعريف المواد'!C2 -> الثانية / الكورس الاول / صباحي | U2: ='تعريف المواد'!B9 -> بدائل الاطرا ف العليا | AA2: ='تعريف المواد'!C9 -> م.م دعاء يوسف محمد | AG2: ='تعريف المواد'!D9 -> 5
A3: عمود1 | B3: عمود2 | C3: عمود3 | D3: عمود4 | E3: عمود5 | F3: عمود6 | G3: عمود7 | H3: عمود8 | I3: عمود9 | J3: عمود10 | K3: عمود11 | L3: عمود12 | M3: عمود13 | N3: عمود14 | O3: عمود15 | P3: عمود16 | Q3: عمود17 | R3: عمود18 | S3: عمود19 | T3: عمود20 | U3: عمود21 | V3: عمود22 | W3: عمود23 | X3: عمود24 | Y3: عمود25 | Z3: عمود26 | AA3: عمود27 | AB3: عمود28 | AC3: عمود29 | AD3: عمود30 | AE3: عمود31 | AF3: عمود32 | AG3: عمود33 | AH3: عمود34 | AI3: عمود35 | AJ3: عمود36
AI4: =IF(AH4>0,AH4/($AG$2*30),"-") -> - | AJ4: =IF(AH4>=3*$AG$2,"انذار نهائي",IF(AH4>=2*$AG$2,"انذار",IF(AH4>=$AG$2,"تنبيه","")))
A5: ت | B5: الاسم الثلاثي | C5: الشعبة | D5: الاسبوع 1 | E5: الاسبوع 2 | F5: الاسبوع 3 | G5: الاسبوع 4 | H5: الاسبوع 5 | I5: الاسبوع 6 | J5: الاسبوع 7 | K5: الاسبوع 8 | L5: الاسبوع 9 | M5: الاسبوع 10 | N5: الاسبوع 11 | O5: الاسبوع 12 | P5: الاسبوع 13 | Q5: الاسبوع 14 | R5: الاسبوع 15 | S5: الاسبوع 16 | T5: الاسبوع 17 | U5: الاسبوع 18 | V5: الاسبوع 19 | W5: الاسبوع 20 | X5: الاسبوع 21 | Y5: الاسبوع 22 | Z5: الاسبوع 23 | AA5: الاسبوع 24 | AB5: الاسبوع 25 | AC5: الاسبوع 26 | AD5: الاسبوع 27 | AE5: الاسبوع 28 | AF5: الاسبوع 29 | AG5: الاسبوع 30 | AH5: مجموع الغيابات | AI5: نسبة الغيابات | AJ5: نوع العقوبة
A6: 1 | B6: =IF('تعريف الاسماء'!B3<=" "," ",'تعريف الاسماء'!B3) -> احمدعدي هريبد بريو | C6: =IF('تعريف الاسماء'!C3<=" "," ",'تعريف الاسماء'!C3) | AH6: =SUM(D6:AG6) -> 0 | AI6: =(IF(AH6>0,(ROUND((AH6/($AG$2*30))*100,0))/100,"-")) -> - | AJ6: =IF(AH6>=3*$AG$2,"انذار نهائي",IF(AH6>=2*$AG$2,"انذار",IF(AH6>=$AG$2,"تنبيه","")))
A7: 2 | B7: =IF('تعريف الاسماء'!B4<=" "," ",'تعريف الاسماء'!B4) -> احمد نزار عباس غبن | C7: =IF('تعريف الاسماء'!C4<=" "," ",'تعريف الاسماء'!C4) | AH7: =SUM(D7:AG7) -> 0 | AI7: =(IF(AH7>0,(ROUND((AH7/($AG$2*30))*100,0))/100,"-")) -> - | AJ7: =IF(AH7>=3*$AG$2,"انذار نهائي",IF(AH7>=2*$AG$2,"انذار",IF(AH7>=$AG$2,"تنبيه","")))
A8: 3 | B8: =IF('تعريف الاسماء'!B5<=" "," ",'تعريف الاسماء'!B5) -> استبرق مرتضى عبد شهيد | C8: =IF('تعريف الاسماء'!C5<=" "," ",'تعريف الاسماء'!C5) | AH8: =SUM(D8:AG8) -> 0 | AI8: =(IF(AH8>0,(ROUND((AH8/($AG$2*30))*100,0))/100,"-")) -> - | AJ8: =IF(AH8>=3*$AG$2,"انذار نهائي",IF(AH8>=2*$AG$2,"انذار",IF(AH8>=$AG$2,"تنبيه","")))
A9: 4 | B9: =IF('تعريف الاسماء'!B6<=" "," ",'تعريف الاسماء'!B6) -> اسراء عمارحاكم وحيد | C9: =IF('تعريف الاسماء'!C6<=" "," ",'تعريف الاسماء'!C6) | AH9: =SUM(D9:AG9) -> 0 | AI9: =(IF(AH9>0,(ROUND((AH9/($AG$2*30))*100,0))/100,"-")) -> - | AJ9: =IF(AH9>=3*$AG$2,"انذار نهائي",IF(AH9>=2*$AG$2,"انذار",IF(AH9>=$AG$2,"تنبيه","")))
A10: 5 | B10: =IF('تعريف الاسماء'!B7<=" "," ",'تعريف الاسماء'!B7) -> افراح نصير علي عودة | C10: =IF('تعريف الاسماء'!C7<=" "," ",'تعريف الاسماء'!C7) | AH10: =SUM(D10:AG10) -> 0 | AI10: =(IF(AH10>0,(ROUND((AH10/($AG$2*30))*100,0))/100,"-")) -> - | AJ10: =IF(AH10>=3*$AG$2,"انذار نهائي",IF(AH10>=2*$AG$2,"انذار",IF(AH10>=$AG$2,"تنبيه","")))
A11: 6 | B11: =IF('تعريف الاسماء'!B8<=" "," ",'تعريف الاسماء'!B8) -> امجد نعيم داود سلمان | C11: =IF('تعريف الاسماء'!C8<=" "," ",'تعريف الاسماء'!C8) | AH11: =SUM(D11:AG11) -> 0 | AI11: =(IF(AH11>0,(ROUND((AH11/($AG$2*30))*100,0))/100,"-")) -> - | AJ11: =IF(AH11>=3*$AG$2,"انذار نهائي",IF(AH11>=2*$AG$2,"انذار",IF(AH11>=$AG$2,"تنبيه","")))
A12: 7 | B12: =IF('تعريف الاسماء'!B9<=" "," ",'تعريف الاسماء'!B9) -> امير سرحان كاطع فرهود | C12: =IF('تعريف الاسماء'!C9<=" "," ",'تعريف الاسماء'!C9) | AH12: =SUM(D12:AG12) -> 0 | AI12: =(IF(AH12>0,(ROUND((AH12/($AG$2*30))*100,0))/100,"-")) -> - | AJ12: =IF(AH12>=3*$AG$2,"انذار نهائي",IF(AH12>=2*$AG$2,"انذار",IF(AH12>=$AG$2,"تنبيه","")))
A13: 8 | B13: =IF('تعريف الاسماء'!B10<=" "," ",'تعريف الاسماء'!B10) -> امير عبد الهادي عبد الأمير | C13: =IF('تعريف الاسماء'!C10<=" "," ",'تعريف الاسماء'!C10) | AH13: =SUM(D13:AG13) -> 0 | AI13: =(IF(AH13>0,(ROUND((AH13/($AG$2*30))*100,0))/100,"-")) -> - | AJ13: =IF(AH13>=3*$AG$2,"انذار نهائي",IF(AH13>=2*$AG$2,"انذار",IF(AH13>=$AG$2,"تنبيه","")))
A14: 9 | B14: =IF('تعريف الاسماء'!B11<=" "," ",'تعريف الاسماء'!B11) -> ايات رزاق جبر جاسم | C14: =IF('تعريف الاسماء'!C11<=" "," ",'تعريف الاسماء'!C11) | AH14: =SUM(D14:AG14) -> 0 | AI14: =(IF(AH14>0,(ROUND((AH14/($AG$2*30))*100,0))/100,"-")) -> - | AJ14: =IF(AH14>=3*$AG$2,"انذار نهائي",IF(AH14>=2*$AG$2,"انذار",IF(AH14>=$AG$2,"تنبيه","")))
A15: 10 | B15: =IF('تعريف الاسماء'!B12<=" "," ",'تعريف الاسماء'!B12) -> ايمان فاضل جنابي مزعل | C15: =IF('تعريف الاسماء'!C12<=" "," ",'تعريف الاسماء'!C12) | AH15: =SUM(D15:AG15) -> 0 | AI15: =(IF(AH15>0,(ROUND((AH15/($AG$2*30))*100,0))/100,"-")) -> - | AJ15: =IF(AH15>=3*$AG$2,"انذار نهائي",IF(AH15>=2*$AG$2,"انذار",IF(AH15>=$AG$2,"تنبيه","")))
A16: 11 | B16: =IF('تعريف الاسماء'!B13<=" "," ",'تعريف الاسماء'!B13) -> بتول خضير شلال رميح | C16: =IF('تعريف الاسماء'!C13<=" "," ",'تعريف الاسماء'!C13) | AH16: =SUM(D16:AG16) -> 0 | AI16: =(IF(AH16>0,(ROUND((AH16/($AG$2*30))*100,0))/100,"-")) -> - | AJ16: =IF(AH16>=3*$AG$2,"انذار نهائي",IF(AH16>=2*$AG$2,"انذار",IF(AH16>=$AG$2,"تنبيه","")))
A17: 12 | B17: =IF('تعريف الاسماء'!B14<=" "," ",'تعريف الاسماء'!B14) -> بتول سعود علكو صباح | C17: =IF('تعريف الاسماء'!C14<=" "," ",'تعريف الاسماء'!C14) | AH17: =SUM(D17:AG17) -> 0 | AI17: =(IF(AH17>0,(ROUND((AH17/($AG$2*30))*100,0))/100,"-")) -> - | AJ17: =IF(AH17>=3*$AG$2,"انذار نهائي",IF(AH17>=2*$AG$2,"انذار",IF(AH17>=$AG$2,"تنبيه","")))
... A405: 400 | B405: =IF('تعريف الاسماء'!B402<=" "," ",'تعريف الاسماء'!B402) | C405: =IF('تعريف الاسماء'!C402<=" "," ",'تعريف الاسماء'!C402) | AH405: =SUM(D405:AG405) -> 0 | AI405: =(IF(AH405>0,(ROUND((AH405/($AG$2*30))*100,0))/100,"-")) -> - | AJ405: =IF(AH405>=3*$AG$2,"انذار نهائي",IF(AH405>=2*$AG$2,"انذار",IF(AH405>=$AG$2,"تنبيه","")))
D406: 0 | E406: 0 | F406: 0 | AJ406: =IF(AH406>=3*$AG$2,"انذار نهائي",IF(AH406>=2*$AG$2,"انذار",IF(AH406>=$AG$2,"تنبيه","")))
D407: 0 | E407: 0 | F407: 0 | AJ407: =IF(AH407>=3*$AG$2,"انذار نهائي",IF(AH407>=2*$AG$2,"انذار",IF(AH407>=$AG$2,"تنبيه","")))
D408: 0 | E408: 0 | F408: 0 | AJ408: =IF(AH408>=3*$AG$2,"انذار نهائي",IF(AH408>=2*$AG$2,"انذار",IF(AH408>=$AG$2,"تنبيه","")))
D409: 0 | E409: 0 | F409: 0 | AJ409: =IF(AH409>=3*$AG$2,"انذار نهائي",IF(AH409>=2*$AG$2,"انذار",IF(AH409>=$AG$2,"تنبيه","")))
D410: 0 | E410: 0 | F410: 0 | AJ410: =IF(AH410>=3*$AG$2,"انذار نهائي",IF(AH410>=2*$AG$2,"انذار",IF(AH410>=$AG$2,"تنبيه","")))
D411: 0 | E411: 0 | F411: 0 | AJ411: =IF(AH411>=3*$AG$2,"انذار نهائي",IF(AH411>=2*$AG$2,"انذار",IF(AH411>=$AG$2,"تنبيه","")))
D412: 0 | E412: 0 | F412: 0 | AJ412: =IF(AH412>=3*$AG$2,"انذار نهائي",IF(AH412>=2*$AG$2,"انذار",IF(AH412>=$AG$2,"تنبيه","")))
D413: 0 | E413: 0 | F413: 0 | AJ413: =IF(AH413>=3*$AG$2,"انذار نهائي",IF(AH413>=2*$AG$2,"انذار",IF(AH413>=$AG$2,"تنبيه","")))
D414: 0 | E414: 0 | F414: 0 | AJ414: =IF(AH414>=3*$AG$2,"انذار نهائي",IF(AH414>=2*$AG$2,"انذار",IF(AH414>=$AG$2,"تنبيه","")))
D415: 0 | E415: 0 | F415: 0 | AJ415: =IF(AH415>=3*$AG$2,"انذار نهائي",IF(AH415>=2*$AG$2,"انذار",IF(AH415>=$AG$2,"تنبيه","")))
D416: 0 | E416: 0 | F416: 0 | AJ416: =IF(AH416>=3*$AG$2,"انذار نهائي",IF(AH416>=2*$AG$2,"انذار",IF(AH416>=$AG$2,"تنبيه","")))
D417: 0 | E417: 0 | F417: 0 | AJ417: =IF(AH417>=3*$AG$2,"انذار نهائي",IF(AH417>=2*$AG$2,"انذار",IF(AH417>=$AG$2,"تنبيه","")))
... D1120: 0 | E1120: 0 | F1120: 0 | AJ1120: =IF(AH1120>=3*$AG$2,"انذار نهائي",IF(AH1120>=2*$AG$2,"انذار",IF(AH1120>=$AG$2,"تنبيه","")))

Sheet مادة 6
B1: الـقـسـم / | C1: ='تعريف المواد'!C1 -> قسم تقنيات صناعة الأطراف والمساند | U1: المادة | AA1: مدرس المادة | AF1: عدد الساعات
B2: المرحلة / | C2: ='تعريف المواد'!C2 -> الثانية / الكورس الاول / صباحي | U2: ='تعريف المواد'!B10 -> خواص مواد | AA2: ='تعريف المواد'!C10 -> م.م مهند عزيز | AG2: ='تعريف المواد'!D10 -> 2
A3: عمود1 | B3: عمود2 | C3: عمود3 | D3: عمود4 | E3: عمود5 | F3: عمود6 | G3: عمود7 | H3: عمود8 | I3: عمود9 | J3: عمود10 | K3: عمود11 | L3: عمود12 | M3: عمود13 | N3: عمود14 | O3: عمود15 | P3: عمود16 | Q3: عمود17 | R3: عمود18 | S3: عمود19 | T3: عمود20 | U3: عمود21 | V3: عمود22 | W3: عمود23 | X3: عمود24 | Y3: عمود25 | Z3: عمود26 | AA3: عمود27 | AB3: عمود28 | AC3: عمود29 | AD3: عمود30 | AE3: عمود31 | AF3: عمود32 | AG3: عمود33 | AH3: عمود34 | AI3: عمود35 | AJ3: عمود36
AI4: =IF(AH4>0,AH4/($AG$2*30),"-") -> - | AJ4: =IF(AH4>=3*$AG$2,"انذار نهائي",IF(AH4>=2*$AG$2,"انذار",IF(AH4>=$AG$2,"تنبيه","")))
A5: ت | B5: الاسم الثلاثي | C5: الشعبة | D5: الاسبوع 1 | E5: الاسبوع 2 | F5: الاسبوع 3 | G5: الاسبوع 4 | H5: الاسبوع 5 | I5: الاسبوع 6 | J5: الاسبوع 7 | K5: الاسبوع 8 | L5: الاسبوع 9 | M5: الاسبوع 10 | N5: الاسبوع 11 | O5: الاسبوع 12 | P5: الاسبوع 13 | Q5: الاسبوع 14 | R5: الاسبوع 15 | S5: الاسبوع 16 | T5: الاسبوع 17 | U5: الاسبوع 18 | V5: الاسبوع 19 | W5: الاسبوع 20 | X5: الاسبوع 21 | Y5: الاسبوع 22 | Z5: الاسبوع 23 | AA5: الاسبوع 24 | AB5: الاسبوع 25 | AC5: الاسبوع 26 | AD5: الاسبوع 27 | AE5: الاسبوع 28 | AF5: الاسبوع 29 | AG5: الاسبوع 30 | AH5: مجموع الغيابات | AI5: نسبة الغيابات | AJ5: نوع العقوبة
A6: 1 | B6: =IF('تعريف الاسماء'!B3<=" "," ",'تعريف الاسماء'!B3) -> احمدعدي هريبد بريو | C6: =IF('تعريف الاسماء'!C3<=" "," ",'تعريف الاسماء'!C3) | AH6: =SUM(D6:AG6) -> 0 | AI6: =(IF(AH6>0,(ROUND((AH6/($AG$2*30))*100,0))/100,"-")) -> - | AJ6: =IF(AH6>=3*$AG$2,"انذار نهائي",IF(AH6>=2*$AG$2,"انذار",IF(AH6>=$AG$2,"تنبيه","")))
A7: 2 | B7: =IF('تعريف الاسماء'!B4<=" "," ",'تعريف الاسماء'!B4) -> احمد نزار عباس غبن | C7: =IF('تعريف الاسماء'!C4<=" "," ",'تعريف الاسماء'!C4) | AH7: =SUM(D7:AG7) -> 0 | AI7: =(IF(AH7>0,(ROUND((AH7/($AG$2*30))*100,0))/100,"-")) -> - | AJ7: =IF(AH7>=3*$AG$2,"انذار نهائي",IF(AH7>=2*$AG$2,"انذار",IF(AH7>=$AG$2,"تنبيه","")))
A8: 3 | B8: =IF('تعريف الاسماء'!B5<=" "," ",'تعريف الاسماء'!B5) -> استبرق مرتضى عبد شهيد | C8: =IF('تعريف الاسماء'!C5<=" "," ",'تعريف الاسماء'!C5) | AH8: =SUM(D8:AG8) -> 0 | AI8: =(IF(AH8>0,(ROUND((AH8/($AG$2*30))*100,0))/100,"-")) -> - | AJ8: =IF(AH8>=3*$AG$2,"انذار نهائي",IF(AH8>=2*$AG$2,"انذار",IF(AH8>=$AG$2,"تنبيه","")))
A9: 4 | B9: =IF('تعريف الاسماء'!B6<=" "," ",'تعريف الاسماء'!B6) -> اسراء عمارحاكم وحيد | C9: =IF('تعريف الاسماء'!C6<=" "," ",'تعريف الاسماء'!C6) | AH9: =SUM(D9:AG9) -> 0 | AI9: =(IF(AH9>0,(ROUND((AH9/($AG$2*30))*100,0))/100,"-")) -> - | AJ9: =IF(AH9>=3*$AG$2,"انذار نهائي",IF(AH9>=2*$AG$2,"انذار",IF(AH9>=$AG$2,"تنبيه","")))
A10: 5 | B10: =IF('تعريف الاسماء'!B7<=" "," ",'تعريف الاسماء'!B7) -> افراح نصير علي عودة | C10: =IF('تعريف الاسماء'!C7<=" "," ",'تعريف الاسماء'!C7) | AH10: =SUM(D10:AG10) -> 0 | AI10: =(IF(AH10>0,(ROUND((AH10/($AG$2*30))*100,0))/100,"-")) -> - | AJ10: =IF(AH10>=3*$AG$2,"انذار نهائي",IF(AH10>=2*$AG$2,"انذار",IF(AH10>=$AG$2,"تنبيه","")))
A11: 6 | B11: =IF('تعريف الاسماء'!B8<=" "," ",'تعريف الاسماء'!B8) -> امجد نعيم داود سلمان | C11: =IF('تعريف الاسماء'!C8<=" "," ",'تعريف الاسماء'!C8) | AH11: =SUM(D11:AG11) -> 0 | AI11: =(IF(AH11>0,(ROUND((AH11/($AG$2*30))*100,0))/100,"-")) -> - | AJ11: =IF(AH11>=3*$AG$2,"انذار نهائي",IF(AH11>=2*$AG$2,"انذار",IF(AH11>=$AG$2,"تنبيه","")))
A12: 7 | B12: =IF('تعريف الاسماء'!B9<=" "," ",'تعريف الاسماء'!B9) -> امير سرحان كاطع فرهود | C12: =IF('تعريف الاسماء'!C9<=" "," ",'تعريف الاسماء'!C9) | AH12: =SUM(D12:AG12) -> 0 | AI12: =(IF(AH12>0,(ROUND((AH12/($AG$2*30))*100,0))/100,"-")) -> - | AJ12: =IF(AH12>=3*$AG$2,"انذار نهائي",IF(AH12>=2*$AG$2,"انذار",IF(AH12>=$AG$2,"تنبيه","")))
A13: 8 | B13: =IF('تعريف الاسماء'!B10<=" "," ",'تعريف الاسماء'!B10) -> امير عبد الهادي عبد الأمير | C13: =IF('تعريف الاسماء'!C10<=" "," ",'تعريف الاسماء'!C10) | AH13: =SUM(D13:AG13) -> 0 | AI13: =(IF(AH13>0,(ROUND((AH13/($AG$2*30))*100,0))/100,"-")) -> - | AJ13: =IF(AH13>=3*$AG$2,"انذار نهائي",IF(AH13>=2*$AG$2,"انذار",IF(AH13>=$AG$2,"تنبيه","")))
A14: 9 | B14: =IF('تعريف الاسماء'!B11<=" "," ",'تعريف الاسماء'!B11) -> ايات رزاق جبر جاسم | C14: =IF('تعريف الاسماء'!C11<=" "," ",'تعريف الاسماء'!C11) | AH14: =SUM(D14:AG14) -> 0 | AI14: =(IF(AH14>0,(ROUND((AH14/($AG$2*30))*100,0))/100,"-")) -> - | AJ14: =IF(AH14>=3*$AG$2,"انذار نهائي",IF(AH14>=2*$AG$2,"انذار",IF(AH14>=$AG$2,"تنبيه","")))
A15: 10 | B15: =IF('تعريف الاسماء'!B12<=" "," ",'تعريف الاسماء'!B12) -> ايمان فاضل جنابي مزعل | C15: =IF('تعريف الاسماء'!C12<=" "," ",'تعريف الاسماء'!C12) | AH15: =SUM(D15:AG15) -> 0 | AI15: =(IF(AH15>0,(ROUND((AH15/($AG$2*30))*100,0))/100,"-")) -> - | AJ15: =IF(AH15>=3*$AG$2,"انذار نهائي",IF(AH15>=2*$AG$2,"انذار",IF(AH15>=$AG$2,"تنبيه","")))
A16: 11 | B16: =IF('تعريف الاسماء'!B13<=" "," ",'تعريف الاسماء'!B13) -> بتول خضير شلال رميح | C16: =IF('تعريف الاسماء'!C13<=" "," ",'تعريف الاسماء'!C13) | AH16: =SUM(D16:AG16) -> 0 | AI16: =(IF(AH16>0,(ROUND((AH16/($AG$2*30))*100,0))/100,"-")) -> - | AJ16: =IF(AH16>=3*$AG$2,"انذار نهائي",IF(AH16>=2*$AG$2,"انذار",IF(AH16>=$AG$2,"تنبيه","")))
A17: 12 | B17: =IF('تعريف الاسماء'!B14<=" "," ",'تعريف الاسماء'!B14) -> بتول سعود علكو صباح | C17: =IF('تعريف الاسماء'!C14<=" "," ",'تعريف الاسماء'!C14) | AH17: =SUM(D17:AG17) -> 0 | AI17: =(IF(AH17>0,(ROUND((AH17/($AG$2*30))*100,0))/100,"-")) -> - | AJ17: =IF(AH17>=3*$AG$2,"انذار نهائي",IF(AH17>=2*$AG$2,"انذار",IF(AH17>=$AG$2,"تنبيه","")))
... A405: 400 | B405: =IF('تعريف الاسماء'!B402<=" "," ",'تعريف الاسماء'!B402) | C405: =IF('تعريف الاسماء'!C402<=" "," ",'تعريف الاسماء'!C402) | AH405: =SUM(D405:AG405) -> 0 | AI405: =(IF(AH405>0,(ROUND((AH405/($AG$2*30))*100,0))/100,"-")) -> - | AJ405: =IF(AH405>=3*$AG$2,"انذار نهائي",IF(AH405>=2*$AG$2,"انذار",IF(AH405>=$AG$2,"تنبيه","")))
D406: 0 | E406: 0 | F406: 0 | AJ406: =IF(AH406>=3*$AG$2,"انذار نهائي",IF(AH406>=2*$AG$2,"انذار",IF(AH406>=$AG$2,"تنبيه","")))
D407: 0 | E407: 0 | F407: 0 | AJ407: =IF(AH407>=3*$AG$2,"انذار نهائي",IF(AH407>=2*$AG$2,"انذار",IF(AH407>=$AG$2,"تنبيه","")))
D408: 0 | E408: 0 | F408: 0 | AJ408: =IF(AH408>=3*$AG$2,"انذار نهائي",IF(AH408>=2*$AG$2,"انذار",IF(AH408>=$AG$2,"تنبيه","")))
D409: 0 | E409: 0 | F409: 0 | AJ409: =IF(AH409>=3*$AG$2,"انذار نهائي",IF(AH409>=2*$AG$2,"انذار",IF(AH409>=$AG$2,"تنبيه","")))
D410: 0 | E410: 0 | F410: 0 | AJ410: =IF(AH410>=3*$AG$2,"انذار نهائي",IF(AH410>=2*$AG$2,"انذار",IF(AH410>=$AG$2,"تنبيه","")))
D411: 0 | E411: 0 | F411: 0 | AJ411: =IF(AH411>=3*$AG$2,"انذار نهائي",IF(AH411>=2*$AG$2,"انذار",IF(AH411>=$AG$2,"تنبيه","")))
D412: 0 | E412: 0 | F412: 0 | AJ412: =IF(AH412>=3*$AG$2,"انذار نهائي",IF(AH412>=2*$AG$2,"انذار",IF(AH412>=$AG$2,"تنبيه","")))
D413: 0 | E413: 0 | F413: 0 | AJ413: =IF(AH413>=3*$AG$2,"انذار نهائي",IF(AH413>=2*$AG$2,"انذار",IF(AH413>=$AG$2,"تنبيه","")))
D414: 0 | E414: 0 | F414: 0 | AJ414: =IF(AH414>=3*$AG$2,"انذار نهائي",IF(AH414>=2*$AG$2,"انذار",IF(AH414>=$AG$2,"تنبيه","")))
D415: 0 | E415: 0 | F415: 0 | AJ415: =IF(AH415>=3*$AG$2,"انذار نهائي",IF(AH415>=2*$AG$2,"انذار",IF(AH415>=$AG$2,"تنبيه","")))
D416: 0 | E416: 0 | F416: 0 | AJ416: =IF(AH416>=3*$AG$2,"انذار نهائي",IF(AH416>=2*$AG$2,"انذار",IF(AH416>=$AG$2,"تنبيه","")))
D417: 0 | E417: 0 | F417: 0 | AJ417: =IF(AH417>=3*$AG$2,"انذار نهائي",IF(AH417>=2*$AG$2,"انذار",IF(AH417>=$AG$2,"تنبيه","")))
... D1120: 0 | E1120: 0 | F1120: 0 | AJ1120: =IF(AH1120>=3*$AG$2,"انذار نهائي",IF(AH1120>=2*$AG$2,"انذار",IF(AH1120>=$AG$2,"تنبيه","")))

Sheet مادة 7
B1: الـقـسـم / | C1: ='تعريف المواد'!C1 -> قسم تقنيات صناعة الأطراف والمساند | U1: المادة | AA1: مدرس المادة | AF1: عدد الساعات
B2: المرحلة / | C2: ='تعريف المواد'!C2 -> الثانية / الكورس الاول / صباحي | U2: ='تعريف المواد'!B11 -> اللغة العربية | AA2: ='تعريف المواد'!C11 -> م.م. حيدر اعلان | AG2: ='تعريف المواد'!D11 -> 2
A3: عمود1 | B3: عمود2 | C3: عمود3 | D3: عمود4 | E3: عمود5 | F3: عمود6 | G3: عمود7 | H3: عمود8 | I3: عمود9 | J3: عمود10 | K3: عمود11 | L3: عمود12 | M3: عمود13 | N3: عمود14 | O3: عمود15 | P3: عمود16 | Q3: عمود17 | R3: عمود18 | S3: عمود19 | T3: عمود20 | U3: عمود21 | V3: عمود22 | W3: عمود23 | X3: عمود24 | Y3: عمود25 | Z3: عمود26 | AA3: عمود27 | AB3: عمود28 | AC3: عمود29 | AD3: عمود30 | AE3: عمود31 | AF3: عمود32 | AG3: عمود33 | AH3: عمود34 | AI3: عمود35 | AJ3: عمود36
AI4: =IF(AH4>0,AH4/($AG$2*30),"-") -> - | AJ4: =IF(AH4>=3*$AG$2,"انذار نهائي",IF(AH4>=2*$AG$2,"انذار",IF(AH4>=$AG$2,"تنبيه","")))
A5: ت | B5: الاسم الثلاثي | C5: الشعبة | D5: الاسبوع 1 | E5: الاسبوع 2 | F5: الاسبوع 3 | G5: الاسبوع 4 | H5: الاسبوع 5 | I5: الاسبوع 6 | J5: الاسبوع 7 | K5: الاسبوع 8 | L5: الاسبوع 9 | M5: الاسبوع 10 | N5: الاسبوع 11 | O5: الاسبوع 12 | P5: الاسبوع 13 | Q5: الاسبوع 14 | R5: الاسبوع 15 | S5: الاسبوع 16 | T5: الاسبوع 17 | U5: الاسبوع 18 | V5: الاسبوع 19 | W5: الاسبوع 20 | X5: الاسبوع 21 | Y5: الاسبوع 22 | Z5: الاسبوع 23 | AA5: الاسبوع 24 | AB5: الاسبوع 25 | AC5: الاسبوع 26 | AD5: الاسبوع 27 | AE5: الاسبوع 28 | AF5: الاسبوع 29 | AG5: الاسبوع 30 | AH5: مجموع الغيابات | AI5: نسبة الغيابات | AJ5: نوع العقوبة
A6: 1 | B6: =IF('تعريف الاسماء'!B3<=" "," ",'تعريف الاسماء'!B3) -> احمدعدي هريبد بريو | C6: =IF('تعريف الاسماء'!C3<=" "," ",'تعريف الاسماء'!C3) | AH6: =SUM(D6:AG6) -> 0 | AI6: =(IF(AH6>0,(ROUND((AH6/($AG$2*30))*100,0))/100,"-")) -> - | AJ6: =IF(AH6>=3*$AG$2,"انذار نهائي",IF(AH6>=2*$AG$2,"انذار",IF(AH6>=$AG$2,"تنبيه","")))
A7: 2 | B7: =IF('تعريف الاسماء'!B4<=" "," ",'تعريف الاسماء'!B4) -> احمد نزار عباس غبن | C7: =IF('تعريف الاسماء'!C4<=" "," ",'تعريف الاسماء'!C4) | AH7: =SUM(D7:AG7) -> 0 | AI7: =(IF(AH7>0,(ROUND((AH7/($AG$2*30))*100,0))/100,"-")) -> - | AJ7: =IF(AH7>=3*$AG$2,"انذار نهائي",IF(AH7>=2*$AG$2,"انذار",IF(AH7>=$AG$2,"تنبيه","")))
A8: 3 | B8: =IF('تعريف الاسماء'!B5<=" "," ",'تعريف الاسماء'!B5) -> استبرق مرتضى عبد شهيد | C8: =IF('تعريف الاسماء'!C5<=" "," ",'تعريف الاسماء'!C5) | AH8: =SUM(D8:AG8) -> 0 | AI8: =(IF(AH8>0,(ROUND((AH8/($AG$2*30))*100,0))/100,"-")) -> - | AJ8: =IF(AH8>=3*$AG$2,"انذار نهائي",IF(AH8>=2*$AG$2,"انذار",IF(AH8>=$AG$2,"تنبيه","")))
A9: 4 | B9: =IF('تعريف الاسماء'!B6<=" "," ",'تعريف الاسماء'!B6) -> اسراء عمارحاكم وحيد | C9: =IF('تعريف الاسماء'!C6<=" "," ",'تعريف الاسماء'!C6) | AH9: =SUM(D9:AG9) -> 0 | AI9: =(IF(AH9>0,(ROUND((AH9/($AG$2*30))*100,0))/100,"-")) -> - | AJ9: =IF(AH9>=3*$AG$2,"انذار نهائي",IF(AH9>=2*$AG$2,"انذار",IF(AH9>=$AG$2,"تنبيه","")))
A10: 5 | B10: =IF('تعريف الاسماء'!B7<=" "," ",'تعريف الاسماء'!B7) -> افراح نصير علي عودة | C10: =IF('تعريف الاسماء'!C7<=" "," ",'تعريف الاسماء'!C7) | AH10: =SUM(D10:AG10) -> 0 | AI10: =(IF(AH10>0,(ROUND((AH10/($AG$2*30))*100,0))/100,"-")) -> - | AJ10: =IF(AH10>=3*$AG$2,"انذار نهائي",IF(AH10>=2*$AG$2,"انذار",IF(AH10>=$AG$2,"تنبيه","")))
A11: 6 | B11: =IF('تعريف الاسماء'!B8<=" "," ",'تعريف الاسماء'!B8) -> امجد نعيم داود سلمان | C11: =IF('تعريف الاسماء'!C8<=" "," ",'تعريف الاسماء'!C8) | AH11: =SUM(D11:AG11) -> 0 | AI11: =(IF(AH11>0,(ROUND((AH11/($AG$2*30))*100,0))/100,"-")) -> - | AJ11: =IF(AH11>=3*$AG$2,"انذار نهائي",IF(AH11>=2*$AG$2,"انذار",IF(AH11>=$AG$2,"تنبيه","")))
A12: 7 | B12: =IF('تعريف الاسماء'!B9<=" "," ",'تعريف الاسماء'!B9) -> امير سرحان كاطع فرهود | C12: =IF('تعريف الاسماء'!C9<=" "," ",'تعريف الاسماء'!C9) | AH12: =SUM(D12:AG12) -> 0 | AI12: =(IF(AH12>0,(ROUND((AH12/($AG$2*30))*100,0))/100,"-")) -> - | AJ12: =IF(AH12>=3*$AG$2,"انذار نهائي",IF(AH12>=2*$AG$2,"انذار",IF(AH12>=$AG$2,"تنبيه","")))
A13: 8 | B13: =IF('تعريف الاسماء'!B10<=" "," ",'تعريف الاسماء'!B10) -> امير عبد الهادي عبد الأمير | C13: =IF('تعريف الاسماء'!C10<=" "," ",'تعريف الاسماء'!C10) | AH13: =SUM(D13:AG13) -> 0 | AI13: =(IF(AH13>0,(ROUND((AH13/($AG$2*30))*100,0))/100,"-")) -> - | AJ13: =IF(AH13>=3*$AG$2,"انذار نهائي",IF(AH13>=2*$AG$2,"انذار",IF(AH13>=$AG$2,"تنبيه","")))
A14: 9 | B14: =IF('تعريف الاسماء'!B11<=" "," ",'تعريف الاسماء'!B11) -> ايات رزاق جبر جاسم | C14: =IF('تعريف الاسماء'!C11<=" "," ",'تعريف الاسماء'!C11) | AH14: =SUM(D14:AG14) -> 0 | AI14: =(IF(AH14>0,(ROUND((AH14/($AG$2*30))*100,0))/100,"-")) -> - | AJ14: =IF(AH14>=3*$AG$2,"انذار نهائي",IF(AH14>=2*$AG$2,"انذار",IF(AH14>=$AG$2,"تنبيه","")))
A15: 10 | B15: =IF('تعريف الاسماء'!B12<=" "," ",'تعريف الاسماء'!B12) -> ايمان فاضل جنابي مزعل | C15: =IF('تعريف الاسماء'!C12<=" "," ",'تعريف الاسماء'!C12) | AH15: =SUM(D15:AG15) -> 0 | AI15: =(IF(AH15>0,(ROUND((AH15/($AG$2*30))*100,0))/100,"-")) -> - | AJ15: =IF(AH15>=3*$AG$2,"انذار نهائي",IF(AH15>=2*$AG$2,"انذار",IF(AH15>=$AG$2,"تنبيه","")))
A16: 11 | B16: =IF('تعريف الاسماء'!B13<=" "," ",'تعريف الاسماء'!B13) -> بتول خضير شلال رميح | C16: =IF('تعريف الاسماء'!C13<=" "," ",'تعريف الاسماء'!C13) | AH16: =SUM(D16:AG16) -> 0 | AI16: =(IF(AH16>0,(ROUND((AH16/($AG$2*30))*100,0))/100,"-")) -> - | AJ16: =IF(AH16>=3*$AG$2,"انذار نهائي",IF(AH16>=2*$AG$2,"انذار",IF(AH16>=$AG$2,"تنبيه","")))
A17: 12 | B17: =IF('تعريف الاسماء'!B14<=" "," ",'تعريف الاسماء'!B14) -> بتول سعود علكو صباح | C17: =IF('تعريف الاسماء'!C14<=" "," ",'تعريف الاسماء'!C14) | AH17: =SUM(D17:AG17) -> 0 | AI17: =(IF(AH17>0,(ROUND((AH17/($AG$2*30))*100,0))/100,"-")) -> - | AJ17: =IF(AH17>=3*$AG$2,"انذار نهائي",IF(AH17>=2*$AG$2,"انذار",IF(AH17>=$AG$2,"تنبيه","")))
... A405: 400 | B405: =IF('تعريف الاسماء'!B402<=" "," ",'تعريف الاسماء'!B402) | C405: =IF('تعريف الاسماء'!C402<=" "," ",'تعريف الاسماء'!C402) | AH405: =SUM(D405:AG405) -> 0 | AI405: =(IF(AH405>0,(ROUND((AH405/($AG$2*30))*100,0))/100,"-")) -> - | AJ405: =IF(AH405>=3*$AG$2,"انذار نهائي",IF(AH405>=2*$AG$2,"انذار",IF(AH405>=$AG$2,"تنبيه","")))
D406: 0 | E406: 0 | F406: 0 | AJ406: =IF(AH406>=3*$AG$2,"انذار نهائي",IF(AH406>=2*$AG$2,"انذار",IF(AH406>=$AG$2,"تنبيه","")))
D407: 0 | E407: 0 | F407: 0 | AJ407: =IF(AH407>=3*$AG$2,"انذار نهائي",IF(AH407>=2*$AG$2,"انذار",IF(AH407>=$AG$2,"تنبيه","")))
D408: 0 | E408: 0 | F408: 0 | AJ408: =IF(AH408>=3*$AG$2,"انذار نهائي",IF(AH408>=2*$AG$2,"انذار",IF(AH408>=$AG$2,"تنبيه","")))
D409: 0 | E409: 0 | F409: 0 | AJ409: =IF(AH409>=3*$AG$2,"انذار نهائي",IF(AH409>=2*$AG$2,"انذار",IF(AH409>=$AG$2,"تنبيه","")))
D410: 0 | E410: 0 | F410: 0 | AJ410: =IF(AH410>=3*$AG$2,"انذار نهائي",IF(AH410>=2*$AG$2,"انذار",IF(AH410>=$AG$2,"تنبيه","")))
D411: 0 | E411: 0 | F411: 0 | AJ411: =IF(AH411>=3*$AG$2,"انذار نهائي",IF(AH411>=2*$AG$2,"انذار",IF(AH411>=$AG$2,"تنبيه","")))
D412: 0 | E412: 0 | F412: 0 | AJ412: =IF(AH412>=3*$AG$2,"انذار نهائي",IF(AH412>=2*$AG$2,"انذار",IF(AH412>=$AG$2,"تنبيه","")))
D413: 0 | E413: 0 | F413: 0 | AJ413: =IF(AH413>=3*$AG$2,"انذار نهائي",IF(AH413>=2*$AG$2,"انذار",IF(AH413>=$AG$2,"تنبيه","")))
D414: 0 | E414: 0 | F414: 0 | AJ414: =IF(AH414>=3*$AG$2,"انذار نهائي",IF(AH414>=2*$AG$2,"انذار",IF(AH414>=$AG$2,"تنبيه","")))
D415: 0 | E415: 0 | F415: 0 | AJ415: =IF(AH415>=3*$AG$2,"انذار نهائي",IF(AH415>=2*$AG$2,"انذار",IF(AH415>=$AG$2,"تنبيه","")))
D416: 0 | E416: 0 | F416: 0 | AJ416: =IF(AH416>=3*$AG$2,"انذار نهائي",IF(AH416>=2*$AG$2,"انذار",IF(AH416>=$AG$2,"تنبيه","")))
D417: 0 | E417: 0 | F417: 0 | AJ417: =IF(AH417>=3*$AG$2,"انذار نهائي",IF(AH417>=2*$AG$2,"انذار",IF(AH417>=$AG$2,"تنبيه","")))
... D1120: 0 | E1120: 0 | F1120: 0 | AJ1120: =IF(AH1120>=3*$AG$2,"انذار نهائي",IF(AH1120>=2*$AG$2,"انذار",IF(AH1120>=$AG$2,"تنبيه","")))

Sheet مادة 8
B1: الـقـسـم / | C1: ='تعريف المواد'!C1 -> قسم تقنيات صناعة الأطراف والمساند | U1: المادة | AA1: مدرس المادة | AF1: عدد الساعات
B2: المرحلة / | C2: ='تعريف المواد'!C2 -> الثانية / الكورس الاول / صباحي | U2: ='تعريف المواد'!B12 -> إجراءات البحث | AA2: ='تعريف المواد'!C12 -> م.م. حيدر اعلان | AG2: ='تعريف المواد'!D12 -> 2
A3: عمود1 | B3: عمود2 | C3: عمود3 | D3: عمود4 | E3: عمود5 | F3: عمود6 | G3: عمود7 | H3: عمود8 | I3: عمود9 | J3: عمود10 | K3: عمود11 | L3: عمود12 | M3: عمود13 | N3: عمود14 | O3: عمود15 | P3: عمود16 | Q3: عمود17 | R3: عمود18 | S3: عمود19 | T3: عمود20 | U3: عمود21 | V3: عمود22 | W3: عمود23 | X3: عمود24 | Y3: عمود25 | Z3: عمود26 | AA3: عمود27 | AB3: عمود28 | AC3: عمود29 | AD3: عمود30 | AE3: عمود31 | AF3: عمود32 | AG3: عمود33 | AH3: عمود34 | AI3: عمود35 | AJ3: عمود36
AI4: =IF(AH4>0,AH4/($AG$2*30),"-") -> - | AJ4: =IF(AH4>=3*$AG$2,"انذار نهائي",IF(AH4>=2*$AG$2,"انذار",IF(AH4>=$AG$2,"تنبيه","")))
A5: ت | B5: الاسم الثلاثي | C5: الشعبة | D5: الاسبوع 1 | E5: الاسبوع 2 | F5: الاسبوع 3 | G5: الاسبوع 4 | H5: الاسبوع 5 | I5: الاسبوع 6 | J5: الاسبوع 7 | K5: الاسبوع 8 | L5: الاسبوع 9 | M5: الاسبوع 10 | N5: الاسبوع 11 | O5: الاسبوع 12 | P5: الاسبوع 13 | Q5: الاسبوع 14 | R5: الاسبوع 15 | S5: الاسبوع 16 | T5: الاسبوع 17 | U5: الاسبوع 18 | V5: الاسبوع 19 | W5: الاسبوع 20 | X5: الاسبوع 21 | Y5: الاسبوع 22 | Z5: الاسبوع 23 | AA5: الاسبوع 24 | AB5: الاسبوع 25 | AC5: الاسبوع 26 | AD5: الاسبوع 27 | AE5: الاسبوع 28 | AF5: الاسبوع 29 | AG5: الاسبوع 30 | AH5: مجموع الغيابات | AI5: نسبة الغيابات | AJ5: نوع العقوبة
A6: 1 | B6: =IF('تعريف الاسماء'!B3<=" "," ",'تعريف الاسماء'!B3) -> احمدعدي هريبد بريو | C6: =IF('تعريف الاسماء'!C3<=" "," ",'تعريف الاسماء'!C3) | AH6: =SUM(D6:AG6) -> 0 | AI6: =(IF(AH6>0,(ROUND((AH6/($AG$2*30))*100,0))/100,"-")) -> - | AJ6: =IF(AH6>=3*$AG$2,"انذار نهائي",IF(AH6>=2*$AG$2,"انذار",IF(AH6>=$AG$2,"تنبيه","")))
A7: 2 | B7: =IF('تعريف الاسماء'!B4<=" "," ",'تعريف الاسماء'!B4) -> احمد نزار عباس غبن | C7: =IF('تعريف الاسماء'!C4<=" "," ",'تعريف الاسماء'!C4) | AH7: =SUM(D7:AG7) -> 0 | AI7: =(IF(AH7>0,(ROUND((AH7/($AG$2*30))*100,0))/100,"-")) -> - | AJ7: =IF(AH7>=3*$AG$2,"انذار نهائي",IF(AH7>=2*$AG$2,"انذار",IF(AH7>=$AG$2,"تنبيه","")))
A8: 3 | B8: =IF('تعريف الاسماء'!B5<=" "," ",'تعريف الاسماء'!B5) -> استبرق مرتضى عبد شهيد | C8: =IF('تعريف الاسماء'!C5<=" "," ",'تعريف الاسماء'!C5) | AH8: =SUM(D8:AG8) -> 0 | AI8: =(IF(AH8>0,(ROUND((AH8/($AG$2*30))*100,0))/100,"-")) -> - | AJ8: =IF(AH8>=3*$AG$2,"انذار نهائي",IF(AH8>=2*$AG$2,"انذار",IF(AH8>=$AG$2,"تنبيه","")))
A9: 4 | B9: =IF('تعريف الاسماء'!B6<=" "," ",'تعريف الاسماء'!B6) -> اسراء عمارحاكم وحيد | C9: =IF('تعريف الاسماء'!C6<=" "," ",'تعريف الاسماء'!C6) | AH9: =SUM(D9:AG9) -> 0 | AI9: =(IF(AH9>0,(ROUND((AH9/($AG$2*30))*100,0))/100,"-")) -> - | AJ9: =IF(AH9>=3*$AG$2,"انذار نهائي",IF(AH9>=2*$AG$2,"انذار",IF(AH9>=$AG$2,"تنبيه","")))
A10: 5 | B10: =IF('تعريف الاسماء'!B7<=" "," ",'تعريف الاسماء'!B7) -> افراح نصير علي عودة | C10: =IF('تعريف الاسماء'!C7<=" "," ",'تعريف الاسماء'!C7) | AH10: =SUM(D10:AG10) -> 0 | AI10: =(IF(AH10>0,(ROUND((AH10/($AG$2*30))*100,0))/100,"-")) -> - | AJ10: =IF(AH10>=3*$AG$2,"انذار نهائي",IF(AH10>=2*$AG$2,"انذار",IF(AH10>=$AG$2,"تنبيه","")))
A11: 6 | B11: =IF('تعريف الاسماء'!B8<=" "," ",'تعريف الاسماء'!B8) -> امجد نعيم داود سلمان | C11: =IF('تعريف الاسماء'!C8<=" "," ",'تعريف الاسماء'!C8) | AH11: =SUM(D11:AG11) -> 0 | AI11: =(IF(AH11>0,(ROUND((AH11/($AG$2*30))*100,0))/100,"-")) -> - | AJ11: =IF(AH11>=3*$AG$2,"انذار نهائي",IF(AH11>=2*$AG$2,"انذار",IF(AH11>=$AG$2,"تنبيه","")))
A12: 7 | B12: =IF('تعريف الاسماء'!B9<=" "," ",'تعريف الاسماء'!B9) -> امير سرحان كاطع فرهود | C12: =IF('تعريف الاسماء'!C9<=" "," ",'تعريف الاسماء'!C9) | AH12: =SUM(D12:AG12) -> 0 | AI12: =(IF(AH12>0,(ROUND((AH12/($AG$2*30))*100,0))/100,"-")) -> - | AJ12: =IF(AH12>=3*$AG$2,"انذار نهائي",IF(AH12>=2*$AG$2,"انذار",IF(AH12>=$AG$2,"تنبيه","")))
A13: 8 | B13: =IF('تعريف الاسماء'!B10<=" "," ",'تعريف الاسماء'!B10) -> امير عبد الهادي عبد الأمير | C13: =IF('تعريف الاسماء'!C10<=" "," ",'تعريف الاسماء'!C10) | AH13: =SUM(D13:AG13) -> 0 | AI13: =(IF(AH13>0,(ROUND((AH13/($AG$2*30))*100,0))/100,"-")) -> - | AJ13: =IF(AH13>=3*$AG$2,"انذار نهائي",IF(AH13>=2*$AG$2,"انذار",IF(AH13>=$AG$2,"تنبيه","")))
A14: 9 | B14: =IF('تعريف الاسماء'!B11<=" "," ",'تعريف الاسماء'!B11) -> ايات رزاق جبر جاسم | C14: =IF('تعريف الاسماء'!C11<=" "," ",'تعريف الاسماء'!C11) | AH14: =SUM(D14:AG14) -> 0 | AI14: =(IF(AH14>0,(ROUND((AH14/($AG$2*30))*100,0))/100,"-")) -> - | AJ14: =IF(AH14>=3*$AG$2,"انذار نهائي",IF(AH14>=2*$AG$2,"انذار",IF(AH14>=$AG$2,"تنبيه","")))
A15: 10 | B15: =IF('تعريف الاسماء'!B12<=" "," ",'تعريف الاسماء'!B12) -> ايمان فاضل جنابي مزعل | C15: =IF('تعريف الاسماء'!C12<=" "," ",'تعريف الاسماء'!C12) | AH15: =SUM(D15:AG15) -> 0 | AI15: =(IF(AH15>0,(ROUND((AH15/($AG$2*30))*100,0))/100,"-")) -> - | AJ15: =IF(AH15>=3*$AG$2,"انذار نهائي",IF(AH15>=2*$AG$2,"انذار",IF(AH15>=$AG$2,"تنبيه","")))
